Workbook

Sheet QSTBKT
A1: TỔ CHỨC BIÊN CHẾ, TRANG BỊ TIỂU ĐOÀN BỘ BINH PHÒNG NGỰ BỜ BIỂN
A3: LỰC LƯỢNG | B3: QUÂN SỐ | C3: TRANG BỊ KỸ THUẬT | N3: VẬT TỰ KỸ THUẬT
C4: Vũ khí bộ binh | H4: Lựu đạn | I4: Cối | L4: PCT | M4: Pháo PK | N4: ON | O4: ĐB
C5: SN | D5: TL | E5: TrL | F5: ĐL | G5: B41, M79 | I5: 60 | J5: 82 | K5: 100 | L5: SPG9 | M5: 12.7
A6: 1. Trong biên chế | B6: =B7 -> 546 | C6: =C7 -> 22 | D6: =D7 -> 289 | E6: =E7 -> 27 | F6: =F7 -> 6 | G6: =G7 -> 54 | H6: =H7 -> 1444 | I6: =I7 -> 6 | ... O6: =O7 -> 0
A7: dBB | B7: 546 | C7: 22 | D7: 289 | E7: 27 | F7: 6 | G7: 54 | H7: 1444 | I7: 6 | J7: 4 | K7: 0 | L7: 3 | M7: 3
A8: 2. LL phối thuộc | B8: =SUM(B9:B17) -> 455 | C8: =SUM(C9:C17) -> 20 | D8: =SUM(D9:D17) -> 197 | E8: =SUM(E9:E17) -> 9 | F8: =SUM(F9:F17) -> 2 | G8: =SUM(G9:G17) -> 18 | H8: =SUM(H9:H17) -> 959 | I8: =SUM(I9:I17) -> 2 | ... N8: =SUM(N9:N17) -> 0 | O8: =SUM(O9:O18) -> 0
A9: 1 cO100/e | B9: 74 | C9: 4 | D9: 30 | H9: 139 | K9: 4
A10: 1 cSPG-9/e | B10: 69 | C10: 4 | D10: 26 | H10: 130 | L10: 6
A11: 1 cSMPK 12,7mm/e | B11: 82 | C11: 4 | D11: 26 | H11: 156 | M11: 6
A12: 1b VTB/e | B12: 28 | D12: 10 | H12: 56
A13: 1 tổ QY/e | B13: 3 | D13: 3 | H13: 6
A14: 1 bHH/f | B14: 19 | D14: 10 | H14: 50
A15: 1 c CB(-)/e | B15: 66 | C15: 4 | D15: 23 | H15: 70
A16: 1 tổ SC/e | B16: 3 | D16: 1 | H16: 6
A17: cBB7/dBB2 | B17: 111 | C17: 4 | D17: 68 | E17: 9 | F17: 2 | G17: 18 | H17: 346 | I17: 2 | J17: 0 | K17: 0 | L17: 0 | M17: 0
A19: Tổng | B19: =B6+B8 -> 1001 | C19: =C7+C8 -> 42 | D19: =D7+D8 -> 486 | E19: =E7+E8 -> 36 | F19: =F7+F8 -> 8 | G19: =G7+G8 -> 72 | H19: =H7+H8 -> 2403 | I19: =I7+I8 -> 8 | J19: =J7+J8 -> 4 | ... O19: =O7+O8 -> 0
A20: TỔ CHỨC BIÊN CHẾ, TRANG BỊ HƯỚNG CHỦ YẾU
A22: LỰC LƯỢNG | B22: QUÂN SỐ | C22: TRANG BỊ KỸ THUẬT | N22: VẬT TỰ KỸ THUẬT
C23: Vũ khí bộ binh | H23: Lựu đạn | I23: Cối | L23: PCT | M23: Pháo PK | N23: ON | O23: ĐB
C24: SN | D24: TL | E24: TrL | F24: ĐL | G24: B41, M79 | I24: 60 | J24: 82 | K24: 100 | L24: SPG9 | M24: 12.7
A25: 1. Trong biên chế | B25: =B26 -> 111 | C25: =C26 -> 4 | D25: =D26 -> 68 | E25: =E26 -> 9 | F25: =F26 -> 2 | G25: =G26 -> 18 | H25: =H26 -> 346 | I25: =I26 -> 2 | ... O25: =O26 -> 0
A26: cBB1 | B26: 111 | C26: 4 | D26: 68 | E26: 9 | F26: 2 | G26: 18 | H26: 346 | I26: 2 | J26: 0 | K26: 0 | L26: 0 | M26: 0
A27: 2. LL tăng cường | B27: =SUM(B28:B34) -> 197 | C27: =SUM(C28:C34) -> 8 | D27: =SUM(D28:D34) -> 93 | E27: =SUM(E28:E34) -> 6 | F27: =SUM(F28:F34) -> 2 | G27: =SUM(G28:G34) -> 12 | H27: =SUM(H28:H34) -> 500 | I27: =SUM(I28:I34) -> 2 | ... O27: =SUM(O28:O34) -> 0
A28: 1 b SPG-9/e | B28: 29 | D28: 11 | H28: 58 | L28: 3
A29: cCo82(-)/d | B29: 34 | C29: 4 | D29: 17 | H29: 94 | J29: 3
A30: b SMPK 12,7mm/e | B30: 35 | D30: 11 | H30: 70 | M30: 3
A31: cBB2 (-) | B31: 82 | C31: 4 | D31: 48 | E31: 6 | F31: 2 | G31: 12 | H31: =346-102 -> 244 | I31: 2
A32: Y tá/d | B32: 1 | D32: 1 | H32: 2
A33: Nuôi quân/d | B33: 7 | D33: 2 | H33: 14
A34: a VTB | B34: 9 | D34: 3 | H34: 18
A36: Tổng | B36: =B25+B27 -> 308 | C36: =C26+C27 -> 12 | D36: =D26+D27 -> 161 | E36: =E26+E27 -> 15 | F36: =F26+F27 -> 4 | G36: =G26+G27 -> 30 | H36: =H26+H27 -> 846 | I36: =I26+I27 -> 4 | J36: =J26+J27 -> 3 | ... O36: =O26+O27 -> 0
A37: TỔ CHỨC BIÊN CHẾ, TRANG BỊ HƯỚNG THỨ YẾU
A39: LỰC LƯỢNG | B39: QUÂN SỐ | C39: TRANG BỊ KỸ THUẬT | N39: VẬT TỰ KỸ THUẬT
C40: Vũ khí bộ binh | H40: Lựu đạn | I40: Cối | L40: PCT | M40: Pháo PK | N40: ON | O40: ĐB
C41: SN | D41: TL | E41: TrL | F41: ĐL | G41: B41, M79 | I41: 60 | J41: 82 | K41: 100 | L41: SPG9 | M41: 12.7
A42: 1. Trong biên chế | B42: =B43 -> 111 | C42: =C43 -> 4 | D42: =D43 -> 68 | E42: =E43 -> 9 | F42: =F43 -> 2 | G42: =G43 -> 18 | H42: =H43 -> 346 | I42: =I43 -> 2 | ... O42: =O43 -> 0
A43: cBB7 | B43: 111 | C43: 4 | D43: 68 | E43: 9 | F43: 2 | G43: 18 | H43: 346 | I43: 2 | J43: 0 | K43: 0 | L43: 0 | M43: 0 | N43: 0 | O43: 0
A44: 2. LL tăng cường | B44: =SUM(B45:B49) -> 85 | C44: =SUM(C45:C49) -> 0 | D44: =SUM(D45:D49) -> 28 | E44: =SUM(E45:E49) -> 0 | F44: =SUM(F45:F49) -> 0 | G44: =SUM(G45:G49) -> 0 | H44: =SUM(H45:H49) -> 168 | I44: =SUM(I45:I49) -> 0 | ... O44: =SUM(O45:O49) -> 0
A45: 1bSPG9/d | B45: 29 | D45: 11 | H45: 58 | L45: 3
...

Sheet TinhHinhVC
A1: Tình hình đạn, VCHC, VTKT
A2: TT | B2: Loại vật chất | C2: ĐVT | D2: Hiện có | G2: Ghi chú
D3: Kho/d | E3: Đơn vị | F3: +
A4: I | B4: ĐẠN
A5: 1 | B5: Đạn K51 (súng ngắn) | C5: CS/k | D5: 0.15 | E5: 1 | F5: =D5+E5 -> 1.15
A6: 2 | B6: Đạn K56 (súng TL, Tr.L) | C6: ,, | D6: 0.15 | E6: 0.5 | F6: =D6+E6 -> 0.65
A7: 3 | B7: Đạn K53 (súng ĐL) | C7: ,, | D7: 0.15 | E7: 0.5 | F7: =D7+E7 -> 0.65
A8: 4 | B8: Đạn B41 | C8: ,, | D8: 0.15 | E8: 0.33 | F8: =D8+E8 -> 0.48
A9: 5 | B9: Đạn SPG-9 | C9: ,, | D9: 0.1 | E9: 0.2 | F9: =D9+E9 -> 0.3
A10: 6 | B10: Đạn Co60 mm | C10: ,, | D10: 0.1 | E10: 0.1 | F10: =D10+E10 -> 0.2
A11: 7 | B11: Đạn Co82 mm | C11: ,, | D11: 0.1 | E11: 0.1 | F11: =D11+E11 -> 0.2
A12: 8 | B12: Đạn Co100 mm | C12: ,, | D12: 0 | E12: 0 | F12: 0
A13: 9 | B13: Đạn SMPK 12,7 | C13: ,, | D13: 0.15 | E13: 0.3 | F13: =D13+E13 -> 0.45
A14: 10 | B14: Lựu đạn | C14: ,, | D14: 100 | E14: 1444 | F14: =D14+E14 -> 1544
A15: II | B15: VẬT CHẤT HẬU CẦN
A16: A | B16: Quân nhu
A17: 1 | B17: Lương thực, thực phẩm | C17: Ngày ăn | D17: 2 | E17: 3 | F17: =D17+E17 -> 5
A18: 2 | B18: Lương khô | C18: Ngày ăn | D18: 1 | E18: 1 | F18: =D18+E18 -> 2
A19: 3 | B19: Đường sữa thương binh | C19: % QS | D19: 1 | E19: 1 | F19: =D19+E19 -> 2
A20: 4 | B20: Quân lương chiến đấu | C20: %QS | E20: 100 | F20: =D20+E20 -> 100
A21: 5 | B21: Quân trang chiến đấu | C21: ,, | E21: 100 | F21: =D21+E21 -> 100
A22: B | B22: Quân y
A23: 6 | B23: Túi y sỹ | C23: Túi | D23: 1 | E23: 1 | F23: =D23+E23 -> 2
A24: 7 | B24: Túi y tá | C24: ,, | D24: 2 | E24: 5 | F24: =D24+E24 -> 7
A25: 8 | B25: Túi cứu thương | C25: ,, | D25: 1 | E25: 8 | F25: =D25+E25 -> 9
A26: 9 | B26: Băng cá nhân | C26: C/người | E26: 1 | F26: =D26+E26 -> 1
A27: C | B27: Doanh trại
A28: 10 | B28: Dầu thắp | C28: Ngày | D28: 2 | E28: 3 | F28: =D28+E28 -> 5
A29: III | B29: VẬT TƯ KỸ THUẬT
A30: 1 | B30: Vật tư quân khí | C30: Tấn | D30: 0.1 | E30: 0.1 | F30: =D30+E30 -> 0.2

Sheet ChiLenhHCKT
A1: 1. Quy định dự trữ, tiêu thụ, bổ sung vật chất
A2: TT | B2: Đạn, vật chất hậu cần, vật tư kỹ thuật | C2: ĐVT | D2: Quy định dự trữ | E2: Phải có 04.00-N | F2: Phải có SCĐ | G2: Tiêu thụ
G3: GĐCB | H3: GĐCĐ
A4: I | B4: Đạn
A5: 1 | B5: Đạn K51 (SN) | C5: Cơ số | D5: =F5+G5+H5 -> 2.2 | E5: 1.45 | F5: 1.2 | H5: 1
A6: 2 | B6: Đạn K56 (TL, TrL) | C6: Cơ số | D6: =F6+G6+H6 -> 1.7 | E6: 1.45 | F6: 0.7 | H6: 1
A7: 3 | B7: Đạn K53 (ĐL) | C7: Cơ số | D7: =F7+G7+H7 -> 1.7 | E7: 1.45 | F7: 0.7 | H7: 1
A8: 4 | B8: Đạn 12,7 mm | C8: Cơ số | D8: =F8+G8+H8 -> 2.3 | E8: 1.75 | F8: 0.8 | H8: 1.5
A9: 5 | B9: Đạn cối 100 mm | C9: Cơ số | D9: =F9+G9+H9 -> 1.35 | E9: 1 | F9: 0.1 | H9: 1.25
A10: 6 | B10: Đạn cối 82 mm | C10: Cơ số | D10: =F10+G10+H10 -> 1.5 | E10: 1.15 | F10: 0.25 | H10: 1.25
A11: 7 | B11: Đạn cối 60 mm | C11: Cơ số | D11: =F11+G11+H11 -> 1.5 | E11: 1.15 | F11: 0.25 | H11: 1.25
A12: 8 | B12: Đạn SPG-9 | C12: Cơ số | D12: =F12+G12+H12 -> 1.35 | E12: 1.15 | F12: 0.35 | H12: 1
A13: 9 | B13: Đạn B41 | C13: Cơ số | D13: =F13+G13+H13 -> 1.78 | E13: 1.45 | F13: 0.53 | H13: 1.25
A14: 10 | B14: Lựu đạn | C14: Quả | D14: =F14+G14+H14 -> 4103 | E14: 2603 | F14: 2603 | H14: 1500
A15: II | B15: Vật chất hậu cần | D15: =F15+G15+H15 -> 0
A16: A | B16: Quân nhu
A17: 1 | B17: LTTP | C17: Ngày | D17: =F17+G17+H17 -> 19 | E17: 7 | F17: 5 | G17: 5 | H17: 9
A18: 2 | B18: Lương khô | C18: Ngày | D18: =F18+G18+H18 -> 4 | E18: 3 | F18: 2 | G18: 0 | H18: 2
A19: 3 | B19: ĐSTB | C19: %QS | D19: =F19+G19+H19 -> 22 | E19: 13 | F19: 8 | H19: 14
A20: 4 | B20: QLCĐ | C20: %QS | D20: =F20+G20+H20 -> 105 | E20: 105 | F20: 100 | H20: 5
A21: 5 | B21: QTCĐ | C21: ,, | D21: =F21+G21+H21 -> 105 | E21: 105 | F21: 100 | H21: 5
A22: B | B22: Quân y
A23: 7 | B23: Túi y sỹ | C23: Túi | D23: =F23+G23+H23 -> 14 | E23: 4 | F23: 2 | H23: 12
A24: 8 | B24: Túi y tá | C24: ,, | D24: =F24+G24+H24 -> 32 | E24: 18 | F24: 8 | H24: 24
A25: 9 | B25: Túi cứu thương | C25: ,, | D25: =F25+G25+H25 -> 43 | E25: 24 | F25: 10 | H25: 33
A26: 10 | B26: Băng cá nhân | C26: C/ng | D26: =F26+G26+H26 -> 3 | E26: 2 | F26: 2 | H26: 1
A27: B | B27: Doanh Trại
A28: 12 | B28: Dầu thắp | C28: Ngày | D28: =F28+G28+H28 -> 19 | E28: 7 | F28: 5 | G28: 5 | H28: 9
A29: III | B29: Vật tư kỹ thuật | C29: Tấn | D29: =F29+G29+H29 -> 1.1 | E29: 1 | F29: 0.5 | G29: 0.1 | H29: 0.5

Sheet DuKienKLVatChat
A1: 1. Dự kiến khối lượng đạn, VHCH, VTKT
A2: STT | B2: Loại VC | C2: Hiện có | D2: Nhu cầu | E2: Bổ sung
A3: 1 | B3: Đạn, lựu đạn | C3: =Đạn!Q28+Đạn!N28 -> 8.9583008 | D3: =Đạn!D28 -> 43.555226 | E3: =D3-C3 -> 34.596926
A4: 2 | B4: Quân nhu | C4: =VCHCVTKT!P8 -> 11.082058 | D4: =VCHCVTKT!F8 -> 27.976806 | E4: =D4-C4 -> 16.894748
A5: 3 | B5: Quân y | C5: =VCHCVTKT!P14 -> 0.12807 | D5: =VCHCVTKT!F14 -> 0.42214 | E5: =D5-C5 -> 0.29407
A6: 4 | B6: Doanh trại | C6: =VCHCVTKT!P19 -> 0.06825 | D6: =VCHCVTKT!F19 -> 0.31698333 | E6: =D6-C6 -> 0.24873333
A7: 5 | B7: Vật tư kỹ thuật | C7: =VCHCVTKT!P21 -> 0.2 | D7: =VCHCVTKT!F21 -> 1.1 | E7: =D7-C7 -> 0.9
B8: Cộng | C8: =C4+C5+C6+C7+C3 -> 20.436679 | D8: =D4+D5+D6+D7+D3 -> 73.371156 | E8: =E4+E5+E6+E7+E3 -> 52.934477

Sheet PhanCapVCHC
A1: 2. Phân cấp một số loại vật chất hậu cần chủ yếu
A2: TT | B2: Loại Vật chất | C2: ĐVT | D2: Phải có 04.00N | G2: Phải có sau chiến đấu
D3: Kho d | E3: Đơn vị | F3: Tổng | G3: Kho d | H3: Đơn vị | I3: Tổng
A4: I | B4: Vật chất hậu cần
B5: Quân nhu
A6: 1 | B6: Gạo, thực phẩm | C6: Ngày ăn | D6: =F6-E6 -> 2 | E6: 5 | F6: =ChiLenhHCKT!E17 -> 7 | G6: =I6-H6 -> 2 | H6: 3 | I6: =ChiLenhHCKT!F17 -> 5
A7: 2 | B7: Lương khô | C7: ,, | D7: =F7-E7 -> 1 | E7: 2 | F7: =ChiLenhHCKT!E18 -> 3 | G7: =I7-H7 -> 1 | H7: 1 | I7: =ChiLenhHCKT!F18 -> 2
A8: 3 | B8: Đường sữa thương binh | C8: %QS | D8: =F8-E8 -> 2 | E8: 11 | F8: =ChiLenhHCKT!E19 -> 13 | G8: =I8-H8 -> 3 | H8: 5 | I8: =ChiLenhHCKT!F19 -> 8
A9: 4 | B9: Quân lương chiến đấu | C9: %QS | D9: =F9-E9 -> 5 | E9: 100 | F9: =ChiLenhHCKT!E20 -> 105 | G9: =I9-H9 -> 0 | H9: 100 | I9: =ChiLenhHCKT!F20 -> 100
A10: 5 | B10: Quân trang chiến đấu | C10: ,, | D10: =F10-E10 -> 5 | E10: 100 | F10: =ChiLenhHCKT!E21 -> 105 | G10: =I10-H10 -> 0 | H10: 100 | I10: =ChiLenhHCKT!F21 -> 100
B11: Quân y
A12: 7 | B12: Túi y sỹ | C12: Túi | D12: =F12-E12 -> 1 | E12: 3 | F12: =ChiLenhHCKT!E23 -> 4 | G12: =I12-H12 -> 1 | H12: 1 | I12: =ChiLenhHCKT!F23 -> 2
A13: 8 | B13: Túi y tá | C13: ,, | D13: =F13-E13 -> 2 | E13: 16 | F13: =ChiLenhHCKT!E24 -> 18 | G13: =I13-H13 -> 2 | H13: 6 | I13: =ChiLenhHCKT!F24 -> 8
A14: 9 | B14: Túi cứu thương | C14: ,, | D14: =F14-E14 -> 1 | E14: 23 | F14: =ChiLenhHCKT!E25 -> 24 | G14: =I14-H14 -> 1 | H14: 9 | I14: =ChiLenhHCKT!F25 -> 10
A15: 10 | B15: Băng cá nhân | C15: C/người | D15: =F15-E15 -> 1 | E15: 1 | F15: =ChiLenhHCKT!E26 -> 2 | G15: =I15-H15 -> 1 | H15: 1 | I15: =ChiLenhHCKT!F26 -> 2
B16: Doanh trại
A17: 11 | B17: Dầu thắp | C17: Ngày | D17: =F17-E17 -> 2 | E17: 5 | F17: =ChiLenhHCKT!E28 -> 7 | G17: =I17-H17 -> 2 | H17: 3 | I17: =ChiLenhHCKT!F28 -> 5
A18: II. | B18: Vật tư kỹ thuật | C18: Tấn | D18: =F18-E18 -> 0.8 | E18: 0.2 | F18: =ChiLenhHCKT!E29 -> 1 | G18: =I18-H18 -> 0.2 | H18: 0.3 | I18: =ChiLenhHCKT!F29 -> 0.5

Sheet DuKienTiLeTBBB
A1: Nội dung | B1: Quân số | C1: Dự kiến tỷ lệ TBBB | J1: Phân bổ chuyển thương
C2: TB | G2: BB | I2: + | J2: Cáng bộ | K2: Tự đi | L2: Tổng
C3: %QS | D3: SN | E3: TBHH | G3: %QS | H3: SN
E4: %TB | F4: SN
A5: Toàn trận | B5: =QSTBKT!B19 -> 1001 | C5: =ChiLenhHCKT!C31 -> 0 | D5: =ROUND(B5*C5/100,0) -> 0 | E5: 20 | F5: =ROUND(D5*E5/100,0) -> 0 | G5: 0.5 | H5: =ROUND(G5*B5/100,0) -> 5 | I5: =ROUND(D5+H5,0) -> 5 | J5: =ROUNDUP(I5/2,0) -> 3 | K5: =I5-J5 -> 2 | L5: =I5 -> 5
A6: HCY | B6: =QSTBKT!B36 -> 308 | C6: 20 | D6: =ROUND(B6*C6/100,0) -> 62 | E6: 20 | F6: =ROUND(D6*E6/100,0) -> 12 | G6: 0.5 | H6: =ROUND(G6*B6/100,0) -> 2 | I6: =ROUND(D6+H6,0) -> 64 | J6: =ROUNDUP(I6/2,0) -> 32 | K6: =I6-J6 -> 32 | L6: =I6 -> 64
A7: HTY | B7: =QSTBKT!B51 -> 196 | C7: 19 | D7: =ROUND(B7*C7/100,0) -> 37 | E7: 20 | F7: =ROUND(D7*E7/100,0) -> 7 | G7: 0.5 | H7: =ROUND(G7*B7/100,0) -> 1 | I7: =ROUND(D7+H7,0) -> 38 | J7: =ROUNDUP(I7/2,0) -> 19 | K7: =I7-J7 -> 19 | L7: =I7 -> 38
A8: PNPS | B8: =QSTBKT!B62 -> 113 | C8: 17 | D8: =ROUND(B8*C8/100,0) -> 19 | E8: 20 | F8: =ROUND(D8*E8/100,0) -> 4 | G8: 0.5 | H8: =ROUND(G8*B8/100,0) -> 1 | I8: =ROUND(D8+H8,0) -> 20 | J8: =ROUNDUP(I8/2,0) -> 10 | K8: =I8-J8 -> 10 | L8: =I8 -> 20
A9: LLCL | B9: =QSTBKT!B81 -> 384 | C9: =ROUND(D9/B9*100,1) -> -30.7 | D9: =D5-D6-D7-D8 -> -118 | E9: 20 | F9: =ROUND(D9*E9/100,0) -> -24 | G9: 0.5 | H9: =ROUND(G9*B9/100,0) -> 2 | I9: =ROUND(D9+H9,0) -> -116 | J9: =ROUNDUP(I9/2,0) -> -58 | K9: =I9-J9 -> -58 | L9: =I9 -> -116
A10: Ngày cao nhất | B10: =B5 -> 1001 | C10: =ChiLenhHCKT!C33 -> 0 | D10: =ROUND(B10*C10/100,0) -> 0 | E10: 20 | F10: =ROUND(D10*E10/100,0) -> 0 | G10: 0.5 | H10: =ROUND(G10*B10/100,0) -> 5 | I10: =ROUND(D10+H10,0) -> 5 | J10: =ROUNDUP(I10/2,0) -> 3 | K10: =I10-J10 -> 2 | L10: =I10 -> 5

Sheet ToChucLucLuong
A1: TT | B1: Nội dung | C1: Quân số | G1: Vũ khí trang bị kỹ thuật | J1: Phân chia lực lượng
C2: SQ | D2: QNCN | E2: HSQ-BS | F2: + | G2: Vũ khí | H2: Xe-máy | I2: TB khác | J2: Bộ phận HC-KT | L2: Lực lượng tăng cường cho đơn vị
J4: QS | K4: TB | L4: QS | M4: TB
A5: 1 | B5: Phân đội HC-KT | C5: =SUM(C6:C12) -> 2 | D5: =SUM(D6:D12) -> 5 | E5: =SUM(E6:E12) -> 54 | F5: =SUM(F6:F12) -> 61
A6: - | B6: TLHC/d | C6: 1 | F6: =SUM(C6:E6) -> 1
A7: - | B7: NVQK | D7: 1 | F7: =SUM(C7:E7) -> 1
A8: - | B8: NVQN | D8: 1 | F8: =SUM(C8:E8) -> 1
A9: - | B9: NVKT | D9: 1 | F9: =SUM(C9:E9) -> 1
A10: - | B10: QY/d | D10: 1 | E10: 2 | F10: =SUM(C10:E10) -> 3
A11: - | B11: bVTB/d | C11: 1 | E11: 27 | F11: =SUM(C11:E11) -> 28
A12: - | B12: bPV/d | D12: 1 | E12: 25 | F12: =SUM(C12:E12) -> 26
A13: 2 | B13: LL tăng cường | C13: =C14+C15+C16 -> 1 | D13: =D14+D15+D16 -> 4 | E13: =E14+E15+E16 -> 29 | F13: =F14+F15+F16 -> 34
A14: - | B14: QY/e | D14: 1 | E14: 2 | F14: =SUM(C14:E14) -> 3
A15: - | B15: bVTB/e | C15: 1 | E15: 27 | F15: =SUM(C15:E15) -> 28
A16: - | B16: Tổ SC/e | D16: 3 | F16: =SUM(C16:E16) -> 3
A17: (+ thêm dòng)
A18: Cộng | C18: =C13+C5 -> 3 | D18: =D13+D5 -> 9 | E18: =E13+E5 -> 83 | F18: =F13+F5 -> 95 | J18: =J13+J5 -> 0 | K18: =K13+K5 -> 0 | L18: =L13+L5 -> 0 | M18: =M13+M5 -> 0

Sheet Đạn
A1: Phụ lục 14: NHU CẦU, TIÊU THỤ, BỔ SUNG ĐẠN TIỂU ĐOÀN BỘ BINH TIẾN CÔNG ĐỊNH PHÒNG NGỰ RỪNG NÚI (phương án)
A2: Loại VC Các chỉ tiêu | B2: ĐẠN BB NHÓM I | H2: ĐẠN BB NHÓM 2 | O2: ĐẠN PPK | R2: LỰU ĐẠN | U2: Cộng
B3: SN | C3: TL | D3: TrL | E3: ĐL | F3: B41 | G3: + | H3: 60 | I3: 82 | K3: 100 | L3: SPG9 | N3: + | O3: 12.7 | Q3: +
B4: CS | C4: CS | D4: CS | E4: CS | F4: CS | G4: Tấn | H4: CS | I4: CS | K4: CS | L4: CS | N4: Tấn | O4: CS | Q4: Tấn | R4: CS | T4: Tấn
A5: TL 1ĐVT (tấn) | B5: =AI40 -> 0.014112 | C5: =AI39 -> 3.2076 | D5: =AI38 -> 0.4752 | E5: =AI37 -> 0.3168 | F5: =#REF! -> #REF! | H5: =#REF! -> #REF! | I5: =#REF! -> #REF! | K5: =#REF! -> #REF! | L5: =#REF! -> #REF! | O5: =#REF! -> #REF! | R5: =AI41 -> 0.00075 | U5: =G5+N5+Q5+T5 -> 0
A6: Tiểu đoàn | B6: =AO40 -> 0.007392 | C6: =AO39 -> 1.9074 | D6: =AO38 -> 0.3564 | E6: =AO37 -> 0.2376 | F6: =#REF! -> #REF! | H6: =#REF! -> #REF! | I6: =#REF! -> #REF! | K6: =#REF! -> #REF! | L6: =#REF! -> #REF! | O6: =#REF! -> #REF! | R6: =AO41 -> 0.00075 | U6: =G6+N6+Q6+T6 -> 0
A7: Phối thuộc | B7: =AU40 -> 0.00672 | C7: =AU39 -> 1.3002 | D7: =AU38 -> 0.1188 | E7: =AU37 -> 0.0792 | F7: =#REF! -> #REF! | H7: =#REF! -> #REF! | I7: =#REF! -> #REF! | K7: =#REF! -> #REF! | L7: =#REF! -> #REF! | O7: =#REF! -> #REF! | R7: =AU41 -> 0.00075 | U7: =G7+N7+Q7+T7 -> 0
A8: 1. NHU CẦU | B8: =B9+B12 -> 2.25 | C8: =C9+C12 -> 1.75 | D8: =D9+D12 -> 1.75 | E8: =E9+E12 -> 1.75 | F8: =F9+F12 -> 1.58 | G8: =B8*$B$5+C8*$C$5+D8*$D$5+E8*$E$5+F8*$F$5 -> #REF! | H8: =H9+H12 -> 1.6 | I8: =I9+I12 -> 1.6 | K8: =K9+K12 -> 1.6 | L8: =L9+L12 -> 1.7 | N8: =H8*$H$5+I8*$I$5+K8*$K$5+L8*$L$5 -> #REF! | O8: =O9+O12 -> 2.05 | Q8: =O8*$O$5 -> #REF! | R8: =R9+R12 -> 1.75 | T8: =R8*$R$5 -> 0.0013125 | U8: =G8+N8+Q8+T8 -> #REF!
A9: 2. TIÊU THỤ | B9: =SUM(B10:B11) -> 1.25 | C9: =SUM(C10:C11) -> 1.25 | D9: =SUM(D10:D11) -> 1.25 | E9: =SUM(E10:E11) -> 1.25 | F9: =SUM(F10:F11) -> 1.25 | G9: =B9*$B$5+C9*$C$5+D9*$D$5+E9*$E$5+F9*$F$5 -> #REF! | H9: =SUM(H10:H11) -> 1.5 | I9: =SUM(I10:I11) -> 1.5 | K9: =SUM(K10:K11) -> 1.5 | L9: =SUM(L10:L11) -> 1.5 | N9: =H9*$H$5+I9*$I$5+K9*$K$5+L9*$L$5 -> #REF! | O9: =SUM(O10:O11) -> 1.75 | Q9: =O9*$O$5 -> #REF! | R9: =SUM(R10:R11) -> 1.25 | T9: =R9*$R$5 -> 0.0009375 | U9: =G9+N9+Q9+T9 -> #REF!
A10: GĐCB | B10: 0 | C10: 0 | D10: 0 | E10: 0 | F10: 0 | G10: =B10*$B$5+C10*$C$5+D10*$D$5+E10*$E$5+F10*$F$5 -> #REF! | H10: 0 | I10: 0 | K10: 0 | L10: 0 | N10: =H10*$H$5+I10*$I$5+K10*$K$5+L10*$L$5 -> #REF! | O10: 0 | Q10: =O10*$O$5 -> #REF! | R10: 0 | T10: =R10*$R$5 -> 0 | U10: =G10+N10+Q10+T10 -> #REF!
A11: GĐCĐ | B11: 1.25 | C11: 1.25 | D11: 1.25 | E11: 1.25 | F11: 1.25 | G11: =B11*$B$5+C11*$C$5+D11*$D$5+E11*$E$5+F11*$F$5 -> #REF! | H11: 1.5 | I11: 1.5 | K11: 1.5 | L11: 1.5 | N11: =H11*$H$5+I11*$I$5+K11*$K$5+L11*$L$5 -> #REF! | O11: 1.75 | Q11: =O11*$O$5 -> #REF! | R11: 1.25 | T11: =R11*$R$5 -> 0.0009375 | U11: =G11+N11+Q11+T11 -> #REF!
A12: 3. PC SCĐ | B12: 1 | C12: 0.5 | D12: 0.5 | E12: 0.5 | F12: 0.33 | G12: =B12*$B$5+C12*$C$5+D12*$D$5+E12*$E$5+F12*$F$5 -> #REF! | H12: 0.1 | I12: 0.1 | K12: 0.1 | L12: 0.2 | N12: =H12*$H$5+I12*$I$5+K12*$K$5+L12*$L$5 -> #REF! | O12: 0.3 | Q12: =O12*$O$5 -> #REF! | R12: 0.5 | T12: =R12*$R$5 -> 0.000375 | U12: =G12+N12+Q12+T12 -> #REF!
A13: 4. HIỆN CÓ | G13: =G14+G15 -> #REF! | N13: =N14+N15 -> #REF! | Q13: =Q14+Q15 -> #REF! | T13: =T14+T15 -> 0.00075 | U13: =G13+N13+Q13+T13 -> #REF!
A14: Tiểu đoàn | B14: 1 | C14: 0.5 | D14: 0.5 | E14: 0.5 | F14: 0.33 | G14: =B14*$B$6+C14*$C$6+D14*$D$6+E14*$E$6+F14*$F$6 -> #REF! | H14: 0.1 | I14: 0.1 | L14: 0.2 | N14: =H14*$H$6+I14*$I$6+K14*$K$6+L14*$L$6 -> #REF! | O14: 0.3 | Q14: =O14*$O$6 -> #REF! | R14: 0.5 | T14: =R14*$R$6 -> 0.000375 | U14: =G14+N14+Q14+T14 -> #REF!
A15: Phối thuộc | B15: 1 | C15: 0.5 | G15: =B15*$B$7+C15*$C$7+D15*$D$7+E15*$E$7+F15*$F$7 -> #REF! | K15: 0.1 | L15: 0.2 | N15: =H15*$H$7+I15*$I$7+K15*$K$7+L15*$L$7 -> #REF! | O15: 0.3 | Q15: =O15*$O$7 -> #REF! | R15: 0.5 | T15: =R15*$R$7 -> 0.000375 | U15: =G15+N15+Q15+T15 -> #REF!
A16: 5. PC TNS | B16: 1.25 | C16: 1.25 | D16: 1.25 | E16: 1.25 | F16: 1.25 | G16: =B16*$B$5+C16*$C$5+D16*$D$5+E16*$E$5+F16*$F$5 -> #REF! | H16: 1.5 | I16: 1.5 | K16: 1.5 | L16: 1.5 | N16: =H16*$H$5+I16*$I$5+K16*$K$5+L16*$L$5 -> #REF! | O16: 1.75 | Q16: =O16*$O$5 -> #REF! | R16: 1.25 | T16: =R16*$R$5 -> 0.0009375 | U16: =G16+N16+Q16+T16 -> #REF!
A17: 6. BỔ SUNG | G17: =G18+G21 -> #REF! | N17: =N18+N21 -> #REF! | Q17: =Q18+Q21 -> #REF! | T17: =T18+T21 -> 0.0015 | U17: =U8-U13 -> #REF!
A18: a.GĐCB | G18: =G19+G20 -> #REF! | N18: =N19+N20 -> #REF! | Q18: =Q19+Q20 -> #REF! | T18: =T19+T20 -> 0.001125 | U18: =G18+N18+Q18+T18 -> #REF!
A19: Tiểu đoàn | B19: =B16-B14 -> 0.25 | C19: =C16-C14 -> 0.75 | D19: =D16-D14 -> 0.75 | E19: =E16-E14 -> 0.75 | F19: =F16-F14 -> 0.92 | G19: =B19*B6+C19*C6+D19*D6+E19*E6+F19*F6 -> #REF! | H19: =H16-H14 -> 1.4 | I19: =I16-I14 -> 1.4 | L19: =L16-L14 -> 1.3 | N19: =H19*H6+I19*I6+K19*K6+L19*L6 -> #REF! | O19: =O16-O14 -> 1.45 | Q19: =O19*O6 -> #REF! | R19: =R16-R14 -> 0.75 | T19: =R19*R6 -> 0.0005625 | U19: =G19+N19+Q19+T19 -> #REF!
A20: Phối thuộc | B20: =B16-B15 -> 0.25 | C20: =C16-C15 -> 0.75 | G20: =B20*B7+C20*C7 -> 0.97683 | K20: =K16-K15 -> 1.4 | L20: =L16-L15 -> 1.3 | N20: =K20*K7+L20*L7 -> #REF! | O20: =O16-O15 -> 1.45 | Q20: =O20*O7 -> #REF! | R20: =R16-R15 -> 0.75 | T20: =R20*R7 -> 0.0005625 | U20: =G20+N20+Q20+T20 -> #REF!
A21: b. GĐCĐ | B21: =B11+B12-B16 -> 1 | C21: =C11+C12-C16 -> 0.5 | D21: =D11+D12-D16 -> 0.5 | E21: =E11+E12-E16 -> 0.5 | F21: =F11+F12-F16 -> 0.33 | G21: =B21*B5+C21*C5+D21*D5+E21*E5+F21*F5 -> #REF! | H21: =H11+H12-H16 -> 0.1 | I21: =I11+I12-I16 -> 0.1 | K21: =K11+K12-K16 -> 0.1 | L21: =L11+L12-L16 -> 0.2 | N21: =H21*H5+I21*I5+K21*K5+L21*L5 -> #REF! | O21: =O11+O12-O16 -> 0.3 | Q21: =O21*O5 -> #REF! | R21: =R11+R12-R16 -> 0.5 | T21: =R5*R21 -> 0.000375 | U21: =T21+Q21+N21+G21 -> #REF!
A24: Loại đạn | B24: Số lượng VK | C24: Nhu cầu | E24: Tiêu thụ | I24: PC SCĐ | L24: Hiện có | R24: PC TQĐ | U24: Kế hoạch tiếp nhận, bảo đảm
E25: GĐCB | G25: GĐCĐ | L25: ĐV | O25: Kho | U25: Trước nổ súng | AA25: thực hành nổ súng
I26: ĐV | J26: Kho | K26: TL | L26: d | M26: PT | N26: TL | O26: d | P26: PT | Q26: TL | R26: ĐV | S26: Kho | T26: TL | U26: ĐV | X26: Kho
C27: Cơ số | D27: TL | E27: Cơ số | F27: TL | G27: Cơ số | H27: TL | I27: Cơ số | J27: Cơ số | L27: Cơ số | M27: Cơ số | O27: Cơ số | P27: Cơ số | R27: Cơ số | S27: Cơ số | U27: d | V27: PT | W27: TL | X27: d | Y27: PT | Z27: TL | AA27: ĐV | AB27: Kho | AC27: TL | AE27: Toàn trận | AK27: Tiểu đoàn | AQ27: Phối thuộc
A28: Toàn d | D28: =D29+D30+D35+D41 -> 43.555226 | H28: =H29+H30+H35+H41 -> 31.667712 | K28: =K29+K30+K35+K41 -> 11.887514 | N28: =N29+N30+N35+N41 -> 7.431282 | Q28: =Q29+Q30+Q35+Q41 -> 1.5270188 | T28: =T29+T30+T35+T41 -> 34.204382 | W28: =W29+W30+W35+W41 -> 24.584358 | Z28: =Z29+Z30+Z35+Z41 -> 2.6139736 | AC28: =AC29+AC30+AC35+AC41 -> 9.350844 | AF28: Số Khẩu | AG28: Tr.l /1V | AH28: SV/CS | AI28: TL 1CS | AL28: Số Khẩu | AM28: Tr.l /1V | AN28: SV/CS | AO28: TL 1CS | AR28: Số Khẩu | AS28: Tr.l /1V | AT28: SV/CS | AU28: TL 1CS
A29: SMPK 12,7mm | B29: =AF29 -> 9 | C29: =ChiLenhHCKT!D8 -> 2.3 | D29: =C29*AI29 -> 4.2228 | G29: =ChiLenhHCKT!H8 -> 1.5 | H29: =G29*AI29 -> 2.754 | I29: 0.3 | J29: =ChiLenhHCKT!F8-Đạn!I29 -> 0.5 | K29: =(I29+J29)*AI29 -> 1.4688 | L29: =TinhHinhVC!E13 -> 0.3 | M29: 0.3 | N29: =L29*AO29+M29*AU29 -> 0.5508 | O29: =TinhHinhVC!D13 -> 0.15 | Q29: =O29*AO29+P29*AU29 -> 0.0918 | R29: 1.25 | S29: =ChiLenhHCKT!E8-Đạn!R29 -> 0.5 | T29: =(R29+S29)*AI29 -> 3.213 | U29: =E29+R29-L29 -> 0.95 | V29: =E29+R29-M29 -> 0.95 | W29: =U29*AO29+V29*AU29 -> 1.7442 | X29: =E29+S29-O29 -> 0.35 | Y29: =E29+S29-P29 -> 0.5 | Z29: =X29*AO29+Y29*AU29 -> 0.8262 | AA29: =G29+I29-R29 -> 0.55 | AB29: =J29-S29 -> 0 | AC29: =(AA29+AB29)*AI29 -> 1.0098 | AE29: SMPK12,7 | AF29: =QSTBKT!M19 -> 9 | AG29: 0.17 | AH29: 1200 | AI29: =AF29*AG29*AH29/1000 -> 1.836 | AK29: SMPK12,7 | AL29: =QSTBKT!M6 -> 3 | AM29: 0.17 | AN29: 1200 | AO29: 0.612 | AQ29: SMPK12,7 | AR29: =QSTBKT!M8 -> 6 | AS29: 0.17 | AT29: 1200 | AU29: =AR29*AS29*AT29/1000 -> 1.224
A30: Đạn BB nhóm 2 | D30: =D31+D32+D33+D34 -> 20.96625 | H30: =H31+H32+H33+H34 -> 17.835 | K30: =K31+K32+K33+K34 -> 3.13125 | N30: =N31+N32+N33+N34 -> 1.9278 | Q30: =Q31+Q32+Q33+Q34 -> 0.4493 | T30: =T31+T32+T33+T34 -> 16.32885 | W30: =W31+W32+W33+W34 -> 13.2312 | Z30: =Z31+Z32+Z33+Z34 -> 0.72055 | AC30: =AC31+AC32+AC33+AC34 -> 4.6374 | AE30: 1CS Đạn BB N2 | AI30: =AF30*AG30*AH30/1000 -> 0 | AK30: 1CS Đạn BB N2 | AQ30: 1CS Đạn BB N2
A31: Cối 100mm | B31: =AF31 -> 4 | C31: =ChiLenhHCKT!D9 -> 1.35 | D31: =C31*AI31 -> 9.936 | G31: =ChiLenhHCKT!H9 -> 1.25 | H31: =G31*AI31 -> 9.2 | I31: 0.1 | J31: =ChiLenhHCKT!F9-Đạn!I31 -> 0 | K31: =(I31+J31)*AI31 -> 0.736 | L31: =TinhHinhVC!E12 -> 0 | M31: 0.1 | N31: =L31*AO31+M31*AU31 -> 0.736 | O31: =TinhHinhVC!D12 -> 0 | Q31: =O31*AO31+P31*AU31 -> 0 | R31: 1 | S31: =ChiLenhHCKT!E9-Đạn!R31 -> 0 | T31: =(R31+S31)*AI31 -> 7.36 | U31: =E31+R31-L31 -> 1 | V31: =E31+R31-M31 -> 0.9 | W31: =U31*AO31+V31*AU31 -> 6.624 | X31: =E31+S31-O31 -> 0 | Y31: =E31+S31-P31 -> 0 | Z31: =X31*AO31+Y31*AU31 -> 0 | AA31: =G31+I31-R31 -> 0.35 | AB31: =J31-S31 -> 0 | AC31: =(AA31+AB31)*AI31 -> 2.576 | AE31: Co100 | AF31: =QSTBKT!K19 -> 4 | AG31: 23 | AH31: 80 | AI31: =AF31*AG31*AH31/1000 -> 7.36 | AK31: Co100 | AL31: =QSTBKT!K6 -> 0 | AM31: 23 | AN31: 80 | AO31: =AL31*AM31*AN31/1000 -> 0 | AQ31: Co100 | AR31: =QSTBKT!K8 -> 4 | AS31: 23 | AT31: 80 | AU31: =AR31*AS31*AT31/1000 -> 7.36
A32: Cối 82mm | B32: =AF32 -> 4 | C32: =ChiLenhHCKT!D10 -> 1.5 | D32: =C32*AI32 -> 3 | G32: =ChiLenhHCKT!H10 -> 1.25 | H32: =G32*AI32 -> 2.5 | I32: 0.1 | J32: =ChiLenhHCKT!F10-Đạn!I32 -> 0.15 | K32: =(I32+J32)*AI32 -> 0.5 | L32: =TinhHinhVC!E11 -> 0.1 | M32: 0 | N32: =L32*AO32+M32*AU32 -> 0.2 | O32: =TinhHinhVC!D11 -> 0.1 | Q32: =O32*AO32+P32*AU32 -> 0.2 | R32: 1 | S32: =ChiLenhHCKT!E10-Đạn!R32 -> 0.15 | T32: =(R32+S32)*AI32 -> 2.3 | U32: =E32+R32-L32 -> 0.9 | V32: =E32+R32-M32 -> 1 | W32: =U32*AO32+V32*AU32 -> 1.8 | X32: =E32+S32-O32 -> 0.05 | Y32: =E32+S32-P32 -> 0.15 | Z32: =X32*AO32+Y32*AU32 -> 0.1 | AA32: =G32+I32-R32 -> 0.35 | AB32: =J32-S32 -> 0 | AC32: =(AA32+AB32)*AI32 -> 0.7 | AE32: Co82 | AF32: =QSTBKT!J19 -> 4 | AG32: 5 | AH32: 100 | AI32: =AF32*AG32*AH32/1000 -> 2 | AK32: Co82 | AL32: =QSTBKT!J6 -> 4 | AM32: 5 | AN32: 100 | AO32: =AL32*AM32*AN32/1000 -> 2 | AQ32: Co82 | AR32: =QSTBKT!J8 -> 0 | AS32: 5 | AT32: 100 | AU32: =AR32*AS32*AT32/1000 -> 0
A33: Cối 60mm | B33: =AF33 -> 8 | C33: =ChiLenhHCKT!D11 -> 1.5 | D33: =C33*AI33 -> 2.016 | G33: =ChiLenhHCKT!H11 -> 1.25 | H33: =G33*AI33 -> 1.68 | I33: 0.1 | J33: =ChiLenhHCKT!F11-Đạn!I33 -> 0.15 | K33: =(I33+J33)*AI33 -> 0.336 | L33: =TinhHinhVC!E10 -> 0.1 | M33: 0 | N33: =L33*AO33+M33*AU33 -> 0.1008 | O33: =TinhHinhVC!D10 -> 0.1 | Q33: =O33*AO33+P33*AU33 -> 0.1008 | R33: 1 | S33: =ChiLenhHCKT!E11-Đạn!R33 -> 0.15 | T33: =(R33+S33)*AI33 -> 1.5456 | U33: =E33+R33-L33 -> 0.9 | V33: =E33+R33-M33 -> 1 | W33: =U33*AO33+V33*AU33 -> 1.2432 | X33: =E33+S33-O33 -> 0.05 | Y33: =E33+S33-P33 -> 0.15 | Z33: =X33*AO33+Y33*AU33 -> 0.1008 | AA33: =G33+I33-R33 -> 0.35 | AB33: =J33-S33 -> 0 | AC33: =(AA33+AB33)*AI33 -> 0.4704 | AE33: Co60 | AF33: =QSTBKT!I19 -> 8 | AG33: 2.1 | AH33: 80 | AI33: =AF33*AG33*AH33/1000 -> 1.344 | AK33: Co60 | AL33: =QSTBKT!I6 -> 6 | AM33: 2.1 | AN33: 80 | AO33: =AL33*AM33*AN33/1000 -> 1.008 | AQ33: Co60 | AR33: =QSTBKT!I8 -> 2 | AS33: 2.1 | AT33: 80 | AU33: =AR33*AS33*AT33/1000 -> 0.336
A34: Súng SPG-9 | B34: =AF34 -> 9 | C34: =ChiLenhHCKT!D12 -> 1.35 | D34: =C34*AI34 -> 6.01425 | G34: =ChiLenhHCKT!H12 -> 1 | H34: =G34*AI34 -> 4.455 | I34: 0.2 | J34: =ChiLenhHCKT!F12-Đạn!I34 -> 0.15 | K34: =(I34+J34)*AI34 -> 1.55925 | L34: =TinhHinhVC!E9 -> 0.2 | M34: 0.2 | N34: =L34*AO34+M34*AU34 -> 0.891 | O34: =TinhHinhVC!D9 -> 0.1 | Q34: =O34*AO34+P34*AU34 -> 0.1485 | R34: 1 | S34: =ChiLenhHCKT!E12-Đạn!R34 -> 0.15 | T34: =(R34+S34)*AI34 -> 5.12325 | U34: =E34+R34-L34 -> 0.8 | V34: =E34+R34-M34 -> 0.8 | W34: =U34*AO34+V34*AU34 -> 3.564 | X34: =E34+S34-O34 -> 0.05 | Y34: =E34+S34-P34 -> 0.15 | Z34: =X34*AO34+Y34*AU34 -> 0.51975 | AA34: =G34+I34-R34 -> 0.2 | AB34: =J34-S34 -> 0 | AC34: =(AA34+AB34)*AI34 -> 0.891 | AE34: SPG9 | AF34: =QSTBKT!L19 -> 9 | AG34: 16.5 | AH34: 30 | AI34: =AF34*AG34*AH34/1000 -> 4.455 | AK34: SPG9 | AL34: =QSTBKT!L6 -> 3 | AM34: 16.5 | AN34: 30 | AO34: =AL34*AM34*AN34/1000 -> 1.485 | AQ34: SPG9 | AR34: =QSTBKT!L8 -> 6 | AS34: 16.5 | AT34: 30 | AU34: =AR34*AS34*AT34/1000 -> 2.97
A35: Đạn BB nhóm 1 | D35: =D36+D37+D38+D39+D40 -> 15.288926 | H35: =H36+H37+H38+H39+H40 -> 9.953712 | K35: =K36+K37+K38+K39+K40 -> 5.3352144 | N35: =N36+N37+N38+N39+N40 -> 3.150432 | Q35: =Q36+Q37+Q38+Q39+Q40 -> 0.9109188 | T35: =T36+T37+T38+T39+T40 -> 12.710282 | W35: =W36+W37+W38+W39+W40 -> 7.806708 | Z35: =Z36+Z37+Z38+Z39+Z40 -> 0.8422236 | AC35: =AC36+AC37+AC38+AC39+AC40 -> 2.578644 | AE35: 1CS Đạn BB N1 | AI35: =AF35*AG35*AH35/1000 -> 0 | AK35: 1CS Đạn BB N1 | AQ35: 1CS Đạn BB N1
A36: Súng B41 | B36: =AF36 -> 72 | C36: =ChiLenhHCKT!D13 -> 1.78 | D36: =C36*AI36 -> 8.45856 | G36: =ChiLenhHCKT!H13 -> 1.25 | H36: =G36*AI36 -> 5.94 | I36: 0.33 | J36: =ChiLenhHCKT!F13-Đạn!I36 -> 0.2 | K36: =(I36+J36)*AI36 -> 2.51856 | L36: =TinhHinhVC!E8 -> 0.33 | M36: 0 | N36: =L36*AO36+M36*AU36 -> 1.17612 | O36: =TinhHinhVC!D8 -> 0.15 | Q36: =O36*AO36+P36*AU36 -> 0.5346 | R36: 1.25 | S36: =ChiLenhHCKT!E13-Đạn!R36 -> 0.2 | T36: =(R36+S36)*AI36 -> 6.8904 | U36: =E36+R36-L36 -> 0.92 | V36: =E36+R36-M36 -> 1.25 | W36: =U36*AO36+V36*AU36 -> 4.76388 | X36: =E36+S36-O36 -> 0.05 | Y36: =E36+S36-P36 -> 0.2 | Z36: =X36*AO36+Y36*AU36 -> 0.4158 | AA36: =G36+I36-R36 -> 0.33 | AB36: =J36-S36 -> 0 | AC36: =(AA36+AB36)*AI36 -> 1.56816 | AE36: B41,M79 | AF36: =QSTBKT!G19 -> 72 | AG36: 5.5 | AH36: 12 | AI36: =AF36*AG36*AH36/1000 -> 4.752 | AK36: B41,M79 | AL36: =QSTBKT!G6 -> 54 | AM36: 5.5 | AN36: 12 | AO36: =AL36*AM36*AN36/1000 -> 3.564 | AQ36: B41,M79 | AR36: =QSTBKT!G8 -> 18 | AS36: 5.5 | AT36: 12 | AU36: =AR36*AS36*AT36/1000 -> 1.188
A37: Súng đại liên | B37: =AF37 -> 8 | C37: =ChiLenhHCKT!D7 -> 1.7 | D37: =C37*AI37 -> 0.53856 | G37: =ChiLenhHCKT!H7 -> 1 | H37: =G37*AI37 -> 0.3168 | I37: 0.5 | J37: =ChiLenhHCKT!F7-Đạn!I37 -> 0.2 | K37: =(I37+J37)*AI37 -> 0.22176 | L37: =TinhHinhVC!E7 -> 0.5 | M37: 0 | N37: =L37*AO37+M37*AU37 -> 0.1188 | O37: =TinhHinhVC!D7 -> 0.15 | Q37: =O37*AO37+P37*AU37 -> 0.03564 | R37: 1.25 | S37: =ChiLenhHCKT!E7-Đạn!R37 -> 0.2 | T37: =(R37+S37)*AI37 -> 0.45936 | U37: =E37+R37-L37 -> 0.75 | V37: =E37+R37-M37 -> 1.25 | W37: =U37*AO37+V37*AU37 -> 0.2772 | X37: =E37+S37-O37 -> 0.05 | Y37: =E37+S37-P37 -> 0.2 | Z37: =X37*AO37+Y37*AU37 -> 0.02772 | AA37: =G37+I37-R37 -> 0.25 | AB37: =J37-S37 -> 0 | AC37: =(AA37+AB37)*AI37 -> 0.0792 | AE37: ĐL | AF37: =QSTBKT!F19 -> 8 | AG37: 0.033 | AH37: 1200 | AI37: =AF37*AG37*AH37/1000 -> 0.3168 | AK37: ĐL | AL37: =QSTBKT!F6 -> 6 | AM37: 0.033 | AN37: 1200 | AO37: =AL37*AM37*AN37/1000 -> 0.2376 | AQ37: ĐL | AR37: =QSTBKT!F8 -> 2 | AS37: 0.033 | AT37: 1200 | AU37: =AR37*AS37*AT37/1000 -> 0.0792
A38: Súng trung liên | B38: =AF38 -> 36 | C38: =ChiLenhHCKT!D6 -> 1.7 | D38: =C38*AI38 -> 0.80784 | G38: =ChiLenhHCKT!H6 -> 1 | H38: =G38*AI38 -> 0.4752 | I38: 0.5 | J38: =ChiLenhHCKT!F6-Đạn!I38 -> 0.2 | K38: =(I38+J38)*AI38 -> 0.33264 | L38: =TinhHinhVC!E6 -> 0.5 | M38: 0.5 | N38: =L38*AO38+M38*AU38 -> 0.2376 | O38: =TinhHinhVC!D6 -> 0.15 | Q38: =O38*AO38+P38*AU38 -> 0.05346 | R38: 1.25 | S38: =ChiLenhHCKT!E6-Đạn!R38 -> 0.2 | T38: =(R38+S38)*AI38 -> 0.68904 | U38: =E38+R38-L38 -> 0.75 | V38: =E38+R38-M38 -> 0.75 | W38: =U38*AO38+V38*AU38 -> 0.3564 | X38: =E38+S38-O38 -> 0.05 | Y38: =E38+S38-P38 -> 0.2 | Z38: =X38*AO38+Y38*AU38 -> 0.04158 | AA38: =G38+I38-R38 -> 0.25 | AB38: =J38-S38 -> 0 | AC38: =(AA38+AB38)*AI38 -> 0.1188 | AE38: TrL | AF38: =QSTBKT!E19 -> 36 | AG38: 0.022 | AH38: 600 | AI38: =AF38*AG38*AH38/1000 -> 0.4752 | AK38: TrL | AL38: =QSTBKT!E6 -> 27 | AM38: 0.022 | AN38: 600 | AO38: =AL38*AM38*AN38/1000 -> 0.3564 | AQ38: TrL | AR38: =QSTBKT!E8 -> 9 | AS38: 0.022 | AT38: 600 | AU38: =AR38*AS38*AT38/1000 -> 0.1188
A39: Súng tiểu liên | B39: =AF39 -> 486 | C39: =ChiLenhHCKT!D6 -> 1.7 | D39: =C39*AI39 -> 5.45292 | G39: =ChiLenhHCKT!H6 -> 1 | H39: =G39*AI39 -> 3.2076 | I39: 0.5 | J39: =ChiLenhHCKT!F6-Đạn!I39 -> 0.2 | K39: =(I39+J39)*AI39 -> 2.24532 | L39: =TinhHinhVC!E6 -> 0.5 | M39: 0.5 | N39: =L39*AO39+M39*AU39 -> 1.6038 | O39: =TinhHinhVC!D6 -> 0.15 | Q39: =O39*AO39+P39*AU39 -> 0.28611 | R39: 1.25 | S39: =ChiLenhHCKT!E6-Đạn!R39 -> 0.2 | T39: =(R39+S39)*AI39 -> 4.65102 | U39: =E39+R39-L39 -> 0.75 | V39: =E39+R39-M39 -> 0.75 | W39: =U39*AO39+V39*AU39 -> 2.4057 | X39: =E39+S39-O39 -> 0.05 | Y39: =E39+S39-P39 -> 0.2 | Z39: =X39*AO39+Y39*AU39 -> 0.35541 | AA39: =G39+I39-R39 -> 0.25 | AB39: =J39-S39 -> 0 | AC39: =(AA39+AB39)*AI39 -> 0.8019 | AE39: TL | AF39: =QSTBKT!D19 -> 486 | AG39: 0.022 | AH39: 300 | AI39: =AF39*AG39*AH39/1000 -> 3.2076 | AK39: TL | AL39: =QSTBKT!D6 -> 289 | AM39: 0.022 | AN39: 300 | AO39: =AL39*AM39*AN39/1000 -> 1.9074 | AQ39: TL | AR39: =QSTBKT!D8 -> 197 | AS39: 0.022 | AT39: 300 | AU39: =AR39*AS39*AT39/1000 -> 1.3002
A40: Súng ngắn | B40: =AF40 -> 42 | C40: =ChiLenhHCKT!D5 -> 2.2 | D40: =C40*AI40 -> 0.0310464 | G40: =ChiLenhHCKT!H5 -> 1 | H40: =G40*AI40 -> 0.014112 | I40: 1 | J40: =ChiLenhHCKT!F5-Đạn!I40 -> 0.2 | K40: =(I40+J40)*AI40 -> 0.0169344 | L40: =TinhHinhVC!E5 -> 1 | M40: 1 | N40: =L40*AO40+M40*AU40 -> 0.014112 | O40: =TinhHinhVC!D5 -> 0.15 | Q40: =O40*AO40+P40*AU40 -> 0.0011088 | R40: 1.25 | S40: =ChiLenhHCKT!E5-Đạn!R40 -> 0.2 | T40: =(R40+S40)*AI40 -> 0.0204624 | U40: =E40+R40-L40 -> 0.25 | V40: =E40+R40-M40 -> 0.25 | W40: =U40*AO40+V40*AU40 -> 0.003528 | X40: =E40+S40-O40 -> 0.05 | Y40: =E40+S40-P40 -> 0.2 | Z40: =X40*AO40+Y40*AU40 -> 0.0017136 | AA40: =G40+I40-R40 -> 0.75 | AB40: =J40-S40 -> 0 | AC40: =(AA40+AB40)*AI40 -> 0.010584 | AE40: SN | AF40: =QSTBKT!C19 -> 42 | AG40: 0.014 | AH40: 24 | AI40: =AF40*AG40*AH40/1000 -> 0.014112 | AK40: SN | AL40: =QSTBKT!C7 -> 22 | AM40: 0.014 | AN40: 24 | AO40: =AL40*AM40*AN40/1000 -> 0.007392 | AQ40: SN | AR40: =QSTBKT!C8 -> 20 | AS40: 0.014 | AT40: 24 | AU40: =AR40*AS40*AT40/1000 -> 0.00672
A41: Lựu đạn | B41: =AF41 -> 2403 | C41: =ChiLenhHCKT!D14 -> 4103 | D41: =C41*AI41 -> 3.07725 | G41: =ChiLenhHCKT!H14 -> 1500 | H41: =G41*AI41 -> 1.125 | I41: 2403 | J41: =ChiLenhHCKT!F14-Đạn!I41 -> 200 | K41: =(I41+J41)*AI41 -> 1.95225 | L41: =TinhHinhVC!E14 -> 1444 | M41: 959 | N41: =L41*AO41+M41*AU41 -> 1.80225 | O41: =TinhHinhVC!D14 -> 100 | Q41: =O41*AO41+P41*AU41 -> 0.075 | R41: 2403 | S41: =ChiLenhHCKT!E14-Đạn!R41 -> 200 | T41: =(R41+S41)*AI41 -> 1.95225 | U41: =E41+R41-L41 -> 959 | V41: =E41+R41-M41 -> 1444 | W41: =U41*AO41+V41*AU41 -> 1.80225 | X41: =E41+S41-O41 -> 100 | Y41: =E41+S41-P41 -> 200 | Z41: =X41*AO41+Y41*AU41 -> 0.225 | AA41: =G41+I41-R41 -> 1500 | AB41: =J41-S41 -> 0 | AC41: =(AA41+AB41)*AI41 -> 1.125 | AE41: Lựu đạn | AF41: =QSTBKT!H19 -> 2403 | AG41: 0.75 | AI41: =0.75/1000 -> 0.00075 | AK41: Lựu đạn | AL41: =QSTBKT!H6 -> 1444 | AM41: 0.75 | AO41: =0.75/1000 -> 0.00075 | AQ41: Lựu đạn | AR41: =QSTBKT!H8 -> 959 | AS41: 0.75 | AU41: =0.75/1000 -> 0.00075
AE42: HƯỚNG CHỦ YẾU
...

Sheet VCHCVTKT
A1: Quy định, phân cấp dự trữ vật chất hậu cần, vật tư kỹ thuật | AE1: Tỷ lệ TBBB
A3: Chỉ tiêu | B3: ĐVT | C3: TL ĐVT | D3: TL ĐVT (d) | E3: TL ĐVT (PT) | F3: Quy định dự trữ, tiêu thụ | L3: Hiện có | Q3: PC TQĐ | S3: Bổ sung | Z3: Kế hoạch tiếp nhận, bảo đảm
F4: Quy định dự trữ | G4: Tiêu thụ | I4: PC SCĐ | L4: Kho/d | N4: ĐV | P4: + | S4: GĐCB | W4: GĐCĐ | Y4: + | Z4: Thời gian | AA4: Địa điểm | AB4: Phương thức | AC4: Trách nhiệm vận chuyển
G5: GĐCB | H5: GĐCĐ | L5: d | M5: PT | N5: d | O5: PT | S5: Kho/d | U5: ĐV | W5: Kho/d | X5: ĐV
I6: Kho/d | J6: ĐV | K6: + | Q6: Kho/d | R6: ĐV | S6: d | T6: PT | U6: d | V6: PT
A7: I. Toàn d | F7: =F8+F14+F19+F21 -> 29.815929 | G7: =G8+G14+G19+G21 -> 6.1894167 | H7: =H8+H14+H19+H21 -> 13.552806 | I7: =I8+I14+I19+I21 -> 3.4803087 | J7: =J8+J14+J19+J21 -> 9.84034 | K7: =K8+K14+K19+K21 -> 13.320649 | L7: =L8+L14+L19+L21 -> 1.855504 | M7: =M8+M14+M19+M21 -> 0 | ... O7: =O8+O14+O19+O21 -> 4.30885 | P7: =L7+M7+N7+O7 -> 11.478378 | Q7: =Q8+Q14+Q19+Q21 -> 4.3279847 | R7: =R8+R14+R19+R21 -> 13.022301 | S7: =S8+S14+S19+S21 -> 0.876124 | T7: =T8+T14+T19 -> 1.5940167 | U7: =U8+U14+U19+U21 -> 5.35964 | V7: =V8+V14+V19 -> 4.2163333 | W7: =ABS(W8)+ABS(W14)+ABS(W19)+ABS(W21) -> 0.847676 | X7: =X8+X14+X19+X21 -> 10.370845 | Y7: =Y8+Y14+Y19+Y21 -> 18.337551
A8: 1. Quân nhu | B8: Tấn | F8: =G8+H8+J8 -> 27.976806 | G8: =SUMPRODUCT($C$9:$C$13,G9:G13)/1000 -> 6.006 | H8: =SUMPRODUCT($C$9:$C$13,H9:H13)/1000 -> 12.598586 | I8: =SUMPRODUCT($C$9:$C$13,I9:I13)/1000 -> 3.160872 | J8: =SUMPRODUCT($C$9:$C$13,J9:J13)/1000 -> 9.37222 | K8: =I8+J8 -> 12.533092 | L8: =SUMPRODUCT($D$9:$D$13,L9:L13)/1000 -> 1.721304 | M8: =SUMPRODUCT($E$9:$E$13,M9:M13)/1000 -> 0 | N8: =SUMPRODUCT($D$9:$D$13,N9:N13)/1000 -> 5.106504 | O8: =SUMPRODUCT($E$9:$E$13,O9:O13)/1000 -> 4.25425 | P8: =L8+M8+N8+O8 -> 11.082058 | Q8: =SUMPRODUCT($C$9:$C$13,Q9:Q13)/1000 -> 3.408548 | R8: =SUMPRODUCT($C$9:$C$13,R9:R13)/1000 -> 12.540814 | S8: =SUMPRODUCT($D$9:$D$13,S9:S13)/1000 -> 0.137904 | T8: =SUMPRODUCT($E$9:$E$13,T9:T13)/1000 -> 1.547 | U8: =SUMPRODUCT($D$9:$D$13,U9:U13)/1000 -> 5.00994 | V8: =SUMPRODUCT($E$9:$E$13,V9:V13)/1000 -> 4.16325 | W8: =SUMPRODUCT($C$9:$C$13,W9:W13)/1000 -> -0.247676 | X8: =SUMPRODUCT($C$9:$C$13,X9:X13)/1000 -> 9.429992 | Y8: =F8-P8 -> 16.894748
A9: LTTP | B9: N/a | C9: =D9+E9 -> 1201.2 | D9: =1.2*QSTBKT!B6 -> 655.2 | E9: =1.2*QSTBKT!B8 -> 546 | F9: =ChiLenhHCKT!D17 -> 19 | G9: =ChiLenhHCKT!G17 -> 5 | H9: =ChiLenhHCKT!H17 -> 9 | I9: =PhanCapVCHC!G6 -> 2 | J9: =PhanCapVCHC!H6 -> 3 | K9: =ChiLenhHCKT!F17 -> 5 | L9: =TinhHinhVC!D17 -> 2 | M9: 0 | N9: =TinhHinhVC!E17 -> 3 | O9: 3 | Q9: =PhanCapVCHC!D6 -> 2 | R9: =PhanCapVCHC!E6 -> 5 | S9: =Q9-L9 -> 0 | T9: =Q9-M9 -> 2 | U9: =G9+R9-N9 -> 7 | V9: =G9+R9-O9 -> 7 | W9: =I9-Q9 -> 0 | X9: =H9+J9-R9 -> 7
A10: Lương khô | B10: N/a | C10: =D10+E10 -> 750.75 | D10: =0.75*QSTBKT!B6 -> 409.5 | E10: =0.75*QSTBKT!B8 -> 341.25 | F10: =ChiLenhHCKT!D18 -> 4 | G10: =ChiLenhHCKT!G18 -> 0 | H10: =ChiLenhHCKT!H18 -> 2 | I10: =PhanCapVCHC!G7 -> 1 | J10: =PhanCapVCHC!H7 -> 1 | K10: =ChiLenhHCKT!F18 -> 2 | L10: =TinhHinhVC!D18 -> 1 | M10: 0 | N10: =TinhHinhVC!E18 -> 1 | O10: 1 | Q10: =PhanCapVCHC!D7 -> 1 | R10: =PhanCapVCHC!E7 -> 2 | S10: =Q10-L10 -> 0 | T10: =Q10-M10 -> 1 | U10: =G10+R10-N10 -> 1 | V10: =G10+R10-O10 -> 1 | W10: =I10-Q10 -> 0 | X10: =H10+J10-R10 -> 1
A11: ĐSTB | B11: %QS | C11: =D11+E11 -> 2.574 | D11: =0.01*QSTBKT!B6*1.8/7 -> 1.404 | E11: =0.01*QSTBKT!B8*1.8/7 -> 1.17 | F11: =ChiLenhHCKT!D19 -> 22 | G11: =ChiLenhHCKT!G19 -> 0 | H11: =ChiLenhHCKT!H19 -> 14 | I11: =PhanCapVCHC!G8 -> 3 | J11: =PhanCapVCHC!H8 -> 5 | K11: =ChiLenhHCKT!F19 -> 8 | L11: =TinhHinhVC!D19 -> 1 | M11: 0 | N11: =TinhHinhVC!E19 -> 1 | O11: 0 | Q11: =PhanCapVCHC!D8 -> 2 | R11: =PhanCapVCHC!E8 -> 11 | S11: =Q11-L11 -> 1 | T11: - | U11: =G11+R11-N11 -> 10 | V11: - | W11: =I11-Q11 -> 1 | X11: =H11+J11-R11 -> 8
A12: QLCĐ | B12: %QS | C12: =D12+E12 -> 20.02 | D12: =0.01*QSTBKT!B6*2 -> 10.92 | E12: =0.01*QSTBKT!B8*2 -> 9.1 | F12: =ChiLenhHCKT!D20 -> 105 | G12: =ChiLenhHCKT!G20 -> 0 | H12: =ChiLenhHCKT!H20 -> 5 | I12: =PhanCapVCHC!G9 -> 0 | J12: =PhanCapVCHC!H9 -> 100 | K12: =ChiLenhHCKT!F20 -> 100 | L12: =TinhHinhVC!D20 -> 0 | M12: 0 | N12: =TinhHinhVC!E20 -> 100 | O12: 100 | Q12: =PhanCapVCHC!D9 -> 5 | R12: =PhanCapVCHC!E9 -> 100 | S12: =Q12-L12 -> 5 | T12: =Q12-M12 -> 5 | U12: =G12+R12-N12 -> 0 | V12: =G12+R12-O12 -> 0 | W12: =I12-Q12 -> -5 | X12: =H12+J12-R12 -> 5
A13: QTCĐ | B13: %QS | C13: =D13+E13 -> 30.03 | D13: =0.01*QSTBKT!B6*3 -> 16.38 | E13: =0.01*QSTBKT!B8*3 -> 13.65 | F13: =ChiLenhHCKT!D21 -> 105 | G13: =ChiLenhHCKT!G21 -> 0 | H13: =ChiLenhHCKT!H21 -> 5 | I13: =PhanCapVCHC!G10 -> 0 | J13: =PhanCapVCHC!H10 -> 100 | K13: =ChiLenhHCKT!F21 -> 100 | L13: =TinhHinhVC!D21 -> 0 | M13: 0 | N13: =TinhHinhVC!E21 -> 100 | O13: 100 | Q13: =PhanCapVCHC!D10 -> 5 | R13: =PhanCapVCHC!E10 -> 100 | S13: =Q13-L13 -> 5 | T13: =Q13-M13 -> 5 | U13: =G13+R13-N13 -> 0 | V13: =G13+R13-O13 -> 0 | W13: =I13-Q13 -> -5 | X13: =H13+J13-R13 -> 5
A14: 2. Quân y | B14: Tấn | F14: =G14+H14+J14 -> 0.42214 | G14: =SUMPRODUCT($C$15:$C$18,G15:G18)/1000 -> 0 | H14: =SUMPRODUCT($C$15:$C$18,H15:H18)/1000 -> 0.30407 | I14: =SUMPRODUCT($C$15:$C$18,I15:I18)/1000 -> 0.08607 | J14: =SUMPRODUCT($C$15:$C$18,J15:J18)/1000 -> 0.11807 | K14: =SUMPRODUCT($C$15:$C$18,K15:K18)/1000 -> 0.20414 | L14: =(SUMPRODUCT($C$15:$C$17,L15:L17)+L18*$D$18)/1000 -> 0.016 | M14: =(SUMPRODUCT($C$15:$C$17,M15:M17)+M18*$E$18)/1000 -> 0 | N14: =(SUMPRODUCT($C$15:$C$17,N15:N17)+N18*$D$18)/1000 -> 0.08022 | O14: =(SUMPRODUCT($C$15:$C$17,O15:O17)+O18*$E$18)/1000 -> 0.03185 | P14: =L14+M14+N14+O14 -> 0.12807 | Q14: =SUMPRODUCT($C$15:$C$18,Q15:Q18)/1000 -> 0.08607 | R14: =SUMPRODUCT($C$15:$C$18,R15:R18)/1000 -> 0.19807 | S14: =(SUMPRODUCT($C$15:$C$17,S15:S17)+S18*$D$18)/1000 -> 0.03822 | T14: =(SUMPRODUCT($C$15:$C$17,T15:T17)+T18*$E$18)/1000 -> 0.03185 | U14: =(SUMPRODUCT($C$15:$C$17,U15:U17)+U18*$D$18)/1000 -> 0.086 | V14: =(SUMPRODUCT($C$15:$C$17,V15:V17)+V18*$E$18)/1000 -> 0 | W14: =SUMPRODUCT($C$15:$C$18,W15:W18)/1000 -> 0 | X14: =SUMPRODUCT($C$15:$C$18,X15:X18)/1000 -> 0.22407 | Y14: =F14-P14 -> 0.29407
A15: Túi y sĩ | B15: Túi | C15: 6 | D15: 6 | E15: 6 | F15: =ChiLenhHCKT!D23 -> 14 | G15: =ChiLenhHCKT!G23 -> 0 | H15: =ChiLenhHCKT!H23 -> 12 | I15: =PhanCapVCHC!G12 -> 1 | J15: =PhanCapVCHC!H12 -> 1 | K15: =ChiLenhHCKT!F23 -> 2 | L15: =TinhHinhVC!D23 -> 1 | M15: 0 | N15: =TinhHinhVC!E23 -> 1 | O15: 0 | Q15: =PhanCapVCHC!D12 -> 1 | R15: =PhanCapVCHC!E12 -> 3 | S15: =Q15-L15 -> 0 | T15: - | U15: =G15+R15-N15 -> 2 | V15: - | W15: =I15-Q15 -> 0 | X15: =H15+J15-R15 -> 10
A16: Túi y tá | B16: Túi | C16: 4 | D16: 4 | E16: 4 | F16: =ChiLenhHCKT!D24 -> 32 | G16: =ChiLenhHCKT!G24 -> 0 | H16: =ChiLenhHCKT!H24 -> 24 | I16: =PhanCapVCHC!G13 -> 2 | J16: =PhanCapVCHC!H13 -> 6 | K16: =ChiLenhHCKT!F24 -> 8 | L16: =TinhHinhVC!D24 -> 2 | M16: 0 | N16: =TinhHinhVC!E24 -> 5 | O16: 0 | Q16: =PhanCapVCHC!D13 -> 2 | R16: =PhanCapVCHC!E13 -> 16 | S16: =Q16-L16 -> 0 | T16: - | U16: =G16+R16-N16 -> 11 | V16: - | W16: =I16-Q16 -> 0 | X16: =H16+J16-R16 -> 14
A17: Túi cứu thương | B17: Túi | C17: 2 | D17: 2 | E17: 2 | F17: =ChiLenhHCKT!D25 -> 43 | G17: =ChiLenhHCKT!G25 -> 0 | H17: =ChiLenhHCKT!H25 -> 33 | I17: =PhanCapVCHC!G14 -> 1 | J17: =PhanCapVCHC!H14 -> 9 | K17: =ChiLenhHCKT!F25 -> 10 | L17: =TinhHinhVC!D25 -> 1 | M17: 0 | N17: =TinhHinhVC!E25 -> 8 | O17: 0 | Q17: =PhanCapVCHC!D14 -> 1 | R17: =PhanCapVCHC!E14 -> 23 | S17: =Q17-L17 -> 0 | T17: - | U17: =G17+R17-N17 -> 15 | V17: - | W17: =I17-Q17 -> 0 | X17: =H17+J17-R17 -> 19
A18: BCN | B18: C/ng | C18: =D18+E18 -> 70.07 | D18: =0.07*QSTBKT!B6 -> 38.22 | E18: =0.07*QSTBKT!B8 -> 31.85 | F18: =ChiLenhHCKT!D26 -> 3 | G18: =ChiLenhHCKT!G26 -> 0 | H18: =ChiLenhHCKT!H26 -> 1 | I18: =PhanCapVCHC!G15 -> 1 | J18: =PhanCapVCHC!H15 -> 1 | K18: =ChiLenhHCKT!F26 -> 2 | L18: =TinhHinhVC!D26 -> 0 | M18: 0 | N18: =TinhHinhVC!E26 -> 1 | O18: 1 | Q18: =PhanCapVCHC!D15 -> 1 | R18: =PhanCapVCHC!E15 -> 1 | S18: =Q18-L18 -> 1 | T18: =Q18-M18 -> 1 | U18: =G18+R18-N18 -> 0 | V18: =G18+R18-O18 -> 0 | W18: =I18-Q18 -> 0 | X18: =H18+J18-R18 -> 1
A19: 3. Doanh trại | B19: Tấn | F19: =$C$20*F20/1000 -> 0.31698333 | G19: =$C$20*G20/1000 -> 0.083416667 | H19: =$C$20*H20/1000 -> 0.15015 | I19: =$C$20*I20/1000 -> 0.033366667 | J19: =$C$20*J20/1000 -> 0.05005 | K19: =$C$20*K20/1000 -> 0.083416667 | L19: =L20*$D$20/1000 -> 0.0182 | M19: =M20*$E$20 -> 0 | N19: =N20*$D$20/1000 -> 0.0273 | O19: =O20*$E$20/1000 -> 0.02275 | P19: =L19+M19+N19+O19 -> 0.06825 | Q19: =$C$20*Q20/1000 -> 0.033366667 | R19: =$C$20*R20/1000 -> 0.083416667 | S19: =S20*$D$20/1000 -> 0 | T19: =T20*$E$20/1000 -> 0.015166667 | U19: =U20*$D$20/1000 -> 0.0637 | V19: =V20*$E$20/1000 -> 0.053083333 | W19: =$C$20*W20/1000 -> 0 | X19: =$C$20*X20/1000 -> 0.11678333 | Y19: =F19-P19 -> 0.24873333
A20: Dầu thắp | B20: ngày | C20: =D20+E20 -> 16.683333 | D20: =QSTBKT!B6*0.5/30 -> 9.1 | E20: =QSTBKT!B8*0.5/30 -> 7.5833333 | F20: =ChiLenhHCKT!D28 -> 19 | G20: =ChiLenhHCKT!G28 -> 5 | H20: =ChiLenhHCKT!H28 -> 9 | I20: =PhanCapVCHC!G17 -> 2 | J20: =PhanCapVCHC!H17 -> 3 | K20: =ChiLenhHCKT!F28 -> 5 | L20: =TinhHinhVC!D28 -> 2 | M20: 0 | N20: =TinhHinhVC!E28 -> 3 | O20: 3 | Q20: =PhanCapVCHC!D17 -> 2 | R20: =PhanCapVCHC!E17 -> 5 | S20: =Q20-L20 -> 0 | T20: =Q20-M20 -> 2 | U20: =G20+R20-N20 -> 7 | V20: =G20+R20-O20 -> 7 | W20: =I20-Q20 -> 0 | X20: =H20+J20-R20 -> 7
A21: 4. VTKT | B21: Tấn | F21: =ChiLenhHCKT!D29 -> 1.1 | G21: =ChiLenhHCKT!G29 -> 0.1 | H21: =ChiLenhHCKT!H29 -> 0.5 | I21: =PhanCapVCHC!G18 -> 0.2 | J21: =PhanCapVCHC!H18 -> 0.3 | K21: =ChiLenhHCKT!F29 -> 0.5 | L21: =TinhHinhVC!D30 -> 0.1 | M21: 0 | N21: =TinhHinhVC!E30 -> 0.1 | O21: 0 | P21: =L21+M21+N21+O21 -> 0.2 | Q21: =PhanCapVCHC!D18 -> 0.8 | R21: =PhanCapVCHC!E18 -> 0.2 | S21: =Q21-L21 -> 0.7 | T21: - | U21: =G21+R21-N21 -> 0.2 | V21: - | W21: =I21-Q21 -> -0.6 | X21: =H21+J21-R21 -> 0.6 | Y21: =F21-P21 -> 0.9
A22: II. Hướng chủ yếu | F22: =F23+F29+F34+F36 -> 9.7256133 | G22: =G23+G29+G34+G36 -> 1.8736667 | H22: =H23+H29+H34+H36 -> 3.93316 | I22: - | J22: =J23+J29+J34+J36 -> 2.91676 | K22: =K23+K29+K34+K36 -> 2.91676 | L22: - | M22: - | N22: =N23+N29+N34+N36 -> 2.91676 | O22: - | P22: =P23+P29+P34+P36 -> 2.91676 | Q22: - | R22: =R23+R29+R34+R36 -> 3.8972267 | S22: - | T22: - | U22: =U23+U29+U34+U36 -> 2.8541333 | V22: - | W22: - | X22: =X23+X29+X34+X36 -> 2.9526933 | Y22: =Y23+Y29+Y34+Y36 -> 6.8088533
A23: 1. Quân nhu | B23: Tấn | F23: =SUMPRODUCT($C$24:$C$28,F24:F28)/1000 -> 9.5634 | G23: =SUMPRODUCT($C$24:$C$28,G24:G28)/1000 -> 1.848 | H23: =SUMPRODUCT($C$24:$C$28,H24:H28)/1000 -> 3.8654 | I23: - | J23: =SUMPRODUCT($C$24:$C$28,J24:J28)/1000 -> 2.8798 | K23: =SUMPRODUCT($C$24:$C$28,K24:K28)/1000 -> 2.8798 | L23: - | M23: - | N23: =SUMPRODUCT($C$24:$C$28,N24:N28)/1000 -> 2.8798 | O23: - | P23: =N23 -> 2.8798 | Q23: - | R23: =SUMPRODUCT($C$24:$C$28,R24:R28)/1000 -> 3.85 | S23: - | T23: - | U23: =G23+R23-N23 -> 2.8182 | V23: - | W23: - | X23: =H23+J23-R23 -> 2.8952 | Y23: =F23-N23 -> 6.6836
A24: LTTP | B24: N/a | C24: =1.2*QSTBKT!B36 -> 369.6 | F24: =F9 -> 19 | G24: =G9 -> 5 | H24: =H9 -> 9 | I24: - | J24: =J9 -> 3 | K24: =J24 -> 3 | L24: - | M24: - | N24: =N9 -> 3 | O24: - | Q24: - | R24: =R9 -> 5 | S24: - | T24: - | U24: =G24+R24-N24 -> 7 | V24: - | W24: - | X24: =H24+J24-R24 -> 7
A25: Lương khô | B25: N/a | C25: =0.75*QSTBKT!B36 -> 231 | F25: =F10 -> 4 | G25: =G10 -> 0 | H25: =H10 -> 2 | I25: - | J25: =J10 -> 1 | K25: =J25 -> 1 | L25: - | M25: - | N25: =N10 -> 1 | O25: - | Q25: - | R25: =R10 -> 2 | S25: - | T25: - | U25: =G25+R25-N25 -> 1 | V25: - | W25: - | X25: =H25+J25-R25 -> 1
A26: ĐSTB | B26: %QS | C26: - | F26: - | G26: - | H26: - | I26: - | J26: - | K26: - | L26: - | M26: - | N26: - | O26: - | P26: - | Q26: - | R26: - | S26: - | T26: - | U26: - | V26: - | W26: - | X26: - | Y26: -
A27: QLCĐ | B27: %QS | C27: =0.01*QSTBKT!B36*2 -> 6.16 | F27: =F12 -> 105 | G27: =G12 -> 0 | H27: =H12 -> 5 | I27: - | J27: =J12 -> 100 | K27: =J27 -> 100 | L27: - | M27: - | N27: =N12 -> 100 | O27: - | Q27: - | R27: =R12 -> 100 | S27: - | T27: - | U27: =G27+R27-N27 -> 0 | V27: - | W27: - | X27: =H27+J27-R27 -> 5
A28: QTCĐ | B28: %QS | C28: =0.01*QSTBKT!B36*3 -> 9.24 | F28: =F13 -> 105 | G28: =G13 -> 0 | H28: =H13 -> 5 | I28: - | J28: =J13 -> 100 | K28: =J28 -> 100 | L28: - | M28: - | N28: =N13 -> 100 | O28: - | Q28: - | R28: =R13 -> 100 | S28: - | T28: - | U28: =G28+R28-N28 -> 0 | V28: - | W28: - | X28: =H28+J28-R28 -> 5
A29: 2. Quân y | B29: Tấn | F29: =SUMPRODUCT($C$30:$C$33,F30:F33)/1000 -> 0.06468 | G29: =SUMPRODUCT($C$30:$C$33,G30:G33)/1000 -> 0 | H29: =SUMPRODUCT($C$30:$C$33,H30:H33)/1000 -> 0.02156 | I29: - | J29: =SUMPRODUCT($C$30:$C$33,J30:J33)/1000 -> 0.02156 | K29: =J29 -> 0.02156 | L29: - | M29: - | N29: =SUMPRODUCT($C$30:$C$33,N30:N33)/1000 -> 0.02156 | O29: - | P29: =N29 -> 0.02156 | Q29: - | R29: =SUMPRODUCT($C$30:$C$33,R30:R33)/1000 -> 0.02156 | S29: - | T29: - | U29: =G29+R29-N29 -> 0 | V29: - | W29: - | X29: =H29+J29-R29 -> 0.02156 | Y29: =F29-N29 -> 0.04312
A30: Túi y sĩ | B30: Túi | C30: 6 | I30: - | K30: =J30 -> 0 | L30: - | M30: - | O30: - | Q30: - | S30: - | T30: - | U30: =G30+R30-N30 -> 0 | V30: - | W30: - | X30: =H30+J30-R30 -> 0
A31: Túi y tá | B31: Túi | C31: 4 | I31: - | K31: =J31 -> 0 | L31: - | M31: - | O31: - | Q31: - | S31: - | T31: - | U31: =G31+R31-N31 -> 0 | V31: - | W31: - | X31: =H31+J31-R31 -> 0
A32: Túi cứu thương | B32: Túi | C32: 2 | I32: - | K32: =J32 -> 0 | L32: - | M32: - | O32: - | Q32: - | S32: - | T32: - | U32: =G32+R32-N32 -> 0 | V32: - | W32: - | X32: =H32+J32-R32 -> 0
A33: BCN | B33: C/ng | C33: =0.07*QSTBKT!B36 -> 21.56 | F33: =F18 -> 3 | G33: =G18 -> 0 | H33: =H18 -> 1 | I33: - | J33: =J18 -> 1 | K33: =J33 -> 1 | L33: - | M33: - | N33: =N18 -> 1 | O33: - | Q33: - | R33: =R18 -> 1 | S33: - | T33: - | U33: =G33+R33-N33 -> 0 | V33: - | W33: - | X33: =H33+J33-R33 -> 1
A34: 3. Doanh trại | B34: Tấn | F34: =F35*$C$35/1000 -> 0.097533333 | G34: =G35*$C$35/1000 -> 0.025666667 | H34: =H35*$C$35/1000 -> 0.0462 | I34: - | J34: =J35*$C$35/1000 -> 0.0154 | K34: =J34 -> 0.0154 | L34: - | M34: - | N34: =N35*$C$35/1000 -> 0.0154 | O34: - | P34: =N34 -> 0.0154 | Q34: - | R34: =R35*$C$35/1000 -> 0.025666667 | S34: - | T34: - | U34: =G34+R34-N34 -> 0.035933333 | V34: - | W34: - | X34: =H34+J34-R34 -> 0.035933333 | Y34: =F34-N34 -> 0.082133333
A35: Dầu thắp | B35: ngày | C35: =0.5*QSTBKT!B36/30 -> 5.1333333 | F35: =F20 -> 19 | G35: =G20 -> 5 | H35: =H20 -> 9 | I35: - | J35: =J20 -> 3 | K35: =J35 -> 3 | L35: - | M35: - | N35: =N20 -> 3 | O35: - | Q35: - | R35: =R20 -> 5 | S35: - | T35: - | U35: =G35+R35-N35 -> 7 | V35: - | W35: - | X35: =H35+J35-R35 -> 7
A36: 4. VTKT | B36: Tấn | I36: - | K36: =J36 -> 0 | L36: - | M36: - | O36: - | P36: =N36 -> 0 | Q36: - | S36: - | T36: - | U36: =G36+R36-N36 -> 0 | V36: - | W36: - | X36: =H36+J36-R36 -> 0 | Y36: =F36-N36 -> 0
A37: II. Hướng thứ yếu | F37: =F38+F44+F49+F51 -> 6.1890267 | G37: =G38+G44+G49+G51 -> 1.1923333 | H37: =H38+H44+H49+H51 -> 2.50292 | I37: - | J37: =J38+J44+J49+J51 -> 1.85612 | K37: =K38+K44+K49+K51 -> 1.85612 | L37: - | M37: - | N37: =N38+N44+N49+N51 -> 1.85612 | O37: - | P37: =P38+P44+P49+P51 -> 1.8424 | Q37: - | R37: =R38+R44+R49+R51 -> 2.4800533 | S37: - | T37: - | U37: =U38+U44+U49+U51 -> 1.8162667 | V37: - | W37: - | X37: =X38+X44+X49+X51 -> 1.8789867 | Y37: =Y38+Y44+Y49+Y51 -> 4.3329067
A38: 1. Quân nhu | B38: Tấn | F38: =SUMPRODUCT($C$39:$C$43,F39:F43)/1000 -> 6.0858 | G38: =SUMPRODUCT($C$39:$C$43,G39:G43)/1000 -> 1.176 | H38: =SUMPRODUCT($C$39:$C$43,H39:H43)/1000 -> 2.4598 | I38: - | J38: =SUMPRODUCT($C$39:$C$43,J39:J43)/1000 -> 1.8326 | K38: =J38 -> 1.8326 | L38: - | M38: - | N38: =SUMPRODUCT($C$39:$C$43,N39:N43)/1000 -> 1.8326 | O38: - | P38: =N38 -> 1.8326 | Q38: - | R38: =SUMPRODUCT($C$39:$C$43,R39:R43)/1000 -> 2.45 | S38: - | T38: - | U38: =SUMPRODUCT($C$39:$C$43,U39:U43)/1000 -> 1.7934 | V38: - | W38: - | X38: =H38+J38-R38 -> 1.8424 | Y38: =F38-N38 -> 4.2532
A39: LTTP | B39: N/a | C39: =1.2*QSTBKT!B51 -> 235.2 | F39: =F24 -> 19 | G39: =G24 -> 5 | H39: =H24 -> 9 | I39: - | J39: =J24 -> 3 | K39: =J39 -> 3 | L39: - | M39: - | N39: =N24 -> 3 | O39: - | Q39: - | R39: =R24 -> 5 | S39: - | T39: - | U39: =G39+R39-N39 -> 7 | V39: - | W39: - | X39: =H39+J39-R39 -> 7
A40: Lương khô | B40: N/a | C40: =0.75*QSTBKT!B51 -> 147 | F40: =F25 -> 4 | G40: =G25 -> 0 | H40: =H25 -> 2 | I40: - | J40: =J25 -> 1 | K40: =J40 -> 1 | L40: - | M40: - | N40: =N25 -> 1 | O40: - | Q40: - | R40: =R25 -> 2 | S40: - | T40: - | U40: =G40+R40-N40 -> 1 | V40: - | W40: - | X40: =H40+J40-R40 -> 1
A41: ĐSTB | B41: %QS | C41: - | F41: =F26 -> - | G41: =G26 -> - | H41: =H26 -> - | I41: - | J41: =J26 -> - | K41: =J41 -> - | L41: - | M41: - | N41: =N26 -> - | O41: - | Q41: - | R41: =R26 -> - | S41: - | T41: - | U41: - | V41: - | W41: - | X41: -
...

Sheet TiLeVuKhiHuHong
A1: TT | B1: Loại VKTBKT | C1: Số lượng TBKT tham gia CĐ | D1: Dự kiến tỷ lệ hư hỏng 1 ngày đêm (%) | E1: Tổng số TBKT hư hỏng | J1: Khả năng sửa chữa trong 1 ngày đêm | M1: Còn lại chưa sửa chữa được
E2: Nhẹ | F2: Vừa | G2: Nặng | H2: Hủy | I2: + | J2: Nhỏ | K2: Vừa | L2: + | M2: Nhỏ | N2: Vừa | O2: Lớn | P2: Hủy
A3: 1 | B3: SMPK 12,7 | C3: =QSTBKT!M19 -> 9 | D3: 8 | E3: =ROUND(I3*0.5,0) -> 1 | F3: =ROUND(I3*0.25,0) -> 0 | G3: =ROUND(I3*0.15,0) -> 0 | H3: =I3-E3-F3-G3 -> 0 | I3: =ROUND(C3*D3/100,0) -> 1 | L3: =J3+K3 -> 0 | M3: =E3-J3 -> 1 | N3: =F3 -> 0 | O3: =G3 -> 0 | P3: =H3 -> 0
A4: 2 | B4: SPG-9 | C4: =QSTBKT!L19 -> 9 | D4: 10 | E4: =ROUND(I4*0.5,0) -> 1 | F4: =ROUND(I4*0.25,0) -> 0 | G4: =ROUND(I4*0.15,0) -> 0 | H4: =I4-E4-F4-G4 -> 0 | I4: =ROUND(C4*D4/100,0) -> 1 | L4: =J4+K4 -> 0 | M4: =E4-J4 -> 1 | N4: =F4 -> 0 | O4: =G4 -> 0 | P4: =H4 -> 0
A5: 3 | B5: Súng ngắn | C5: =QSTBKT!C19 -> 42 | D5: 4 | E5: =ROUND(I5*0.5,0) -> 1 | F5: =ROUND(I5*0.25,0) -> 1 | G5: =ROUND(I5*0.15,0) -> 0 | H5: =I5-E5-F5-G5 -> 0 | I5: =ROUND(C5*D5/100,0) -> 2 | L5: =J5+K5 -> 0 | M5: =E5-J5 -> 1 | N5: =F5 -> 1 | O5: =G5 -> 0 | P5: =H5 -> 0
A6: 4 | B6: Tiểu liên | C6: =QSTBKT!D19 -> 486 | D6: 4 | E6: =ROUND(I6*0.5,0) -> 10 | F6: =ROUND(I6*0.25,0) -> 5 | G6: =ROUND(I6*0.15,0) -> 3 | H6: =I6-E6-F6-G6 -> 1 | I6: =ROUND(C6*D6/100,0) -> 19 | L6: =J6+K6 -> 0 | M6: =E6-J6 -> 10 | N6: =F6 -> 5 | O6: =G6 -> 3 | P6: =H6 -> 1
A7: 5 | B7: Trung liên | C7: =QSTBKT!E19 -> 36 | D7: 4 | E7: =ROUND(I7*0.5,0) -> 1 | F7: =ROUND(I7*0.25,0) -> 0 | G7: =ROUND(I7*0.15,0) -> 0 | H7: =I7-E7-F7-G7 -> 0 | I7: =ROUND(C7*D7/100,0) -> 1 | L7: =J7+K7 -> 0 | M7: =E7-J7 -> 1 | N7: =F7 -> 0 | O7: =G7 -> 0 | P7: =H7 -> 0
A8: 6 | B8: Đại liên | C8: =QSTBKT!F19 -> 8 | D8: 4 | E8: =ROUND(I8*0.5,0) -> 0 | F8: =ROUND(I8*0.25,0) -> 0 | G8: =ROUND(I8*0.15,0) -> 0 | H8: =I8-E8-F8-G8 -> 0 | I8: =ROUND(C8*D8/100,0) -> 0 | L8: =J8+K8 -> 0 | M8: =E8-J8 -> 0 | N8: =F8 -> 0 | O8: =G8 -> 0 | P8: =H8 -> 0
A9: 7 | B9: B41 | C9: =QSTBKT!G19 -> 72 | D9: 4 | E9: =ROUND(I9*0.5,0) -> 2 | F9: =ROUND(I9*0.25,0) -> 1 | G9: =ROUND(I9*0.15,0) -> 0 | H9: =I9-E9-F9-G9 -> 0 | I9: =ROUND(C9*D9/100,0) -> 3 | L9: =J9+K9 -> 0 | M9: =E9-J9 -> 2 | N9: =F9 -> 1 | O9: =G9 -> 0 | P9: =H9 -> 0
A10: 8 | B10: Cối 100 | C10: =QSTBKT!K19 -> 4 | D10: 10 | E10: =ROUND(I10*0.5,0) -> 0 | F10: =ROUND(I10*0.25,0) -> 0 | G10: =ROUND(I10*0.15,0) -> 0 | H10: =I10-E10-F10-G10 -> 0 | I10: =ROUND(C10*D10/100,0) -> 0 | L10: =J10+K10 -> 0 | M10: =E10-J10 -> 0 | N10: =F10 -> 0 | O10: =G10 -> 0 | P10: =H10 -> 0
A11: 9 | B11: Cối 82 | C11: =QSTBKT!J19 -> 4 | D11: 10 | E11: =ROUND(I11*0.5,0) -> 0 | F11: =ROUND(I11*0.25,0) -> 0 | G11: =ROUND(I11*0.15,0) -> 0 | H11: =I11-E11-F11-G11 -> 0 | I11: =ROUND(C11*D11/100,0) -> 0 | L11: =J11+K11 -> 0 | M11: =E11-J11 -> 0 | N11: =F11 -> 0 | O11: =G11 -> 0 | P11: =H11 -> 0
A12: 10 | B12: Cối 60 | C12: =QSTBKT!I19 -> 8 | D12: 10 | E12: =ROUND(I12*0.5,0) -> 1 | F12: =ROUND(I12*0.25,0) -> 0 | G12: =ROUND(I12*0.15,0) -> 0 | H12: =I12-E12-F12-G12 -> 0 | I12: =ROUND(C12*D12/100,0) -> 1 | L12: =J12+K12 -> 0 | M12: =E12-J12 -> 1 | N12: =F12 -> 0 | O12: =G12 -> 0 | P12: =H12 -> 0

Sheet KhoiLuongVanTai
A1: 2. Khối lượng vận tải và phân cấp vận chuyển
A2: Nội dung | B2: Khối lượng vận chuyển | M2: Ghi chú
B3: Trang bị kỹ thuật | F3: Vật chất hậu cần | J3: Vật chất khác | K3: Cộng | L3: Người
B4: VKTB | C4: Đạn | D4: VTKT | E4: + | F4: QN | G4: QY | H4: DT | I4: +
A5: Đơn vị tính | B5: tấn | C5: tấn | D5: tấn | E5: tấn | F5: tấn | G5: tấn | H5: tấn | I5: tấn | J5: tấn | K5: tấn | L5: người
A6: Toàn trận | B6: =B7+B11 -> 0 | C6: =C7+C11 -> 0 | D6: =D7+D11 -> 0 | E6: =E7+E11 -> 0 | F6: =F7+F11 -> 0 | G6: =G7+G11 -> 0 | H6: =H7+H11 -> 0 | I6: =I7+I11 -> 0 | J6: =J7+J11 -> 0 | K6: =E6+I6 -> 0 | L6: =ROUNDUP(DuKienTiLeTBBB!I5/2,0) -> 3
A7: GĐCB | B7: =B8+B9+B10 -> 0 | C7: =C8+C9+C10 -> 0 | D7: =D8+D9+D10 -> 0 | E7: =E8+E9+E10 -> 0 | F7: =F8+F9+F10 -> 0 | G7: =G8+G9+G10 -> 0 | H7: =H8+H9+H10 -> 0 | I7: =I8+I9+I10 -> 0 | ... K7: =K8+K9+K10 -> 0
A8: Trên chuyển
A9: Cấp mình
A10: Dưới chuyển
A11: GĐCĐ | B11: =B12+B13+B14 -> 0 | C11: =C12+C13+C14 -> 0 | D11: =D12+D13+D14 -> 0 | E11: =E12+E13+E14 -> 0 | F11: =F12+F13+F14 -> 0 | G11: =G12+G13+G14 -> 0 | H11: =H12+H13+H14 -> 0 | I11: =I12+I13+I14 -> 0 | ... K11: =K12+K13+K14 -> 0 | L11: =L6 -> 3
A12: Trên chuyển
A13: Cấp mình
A14: Dưới chuyển

Sheet KeHoachVanChuyen
A2: Nội dung, Đơn vị được vận chuyển | B2: Người | C2: TBKT, vật chất HC, KT | E2: Địa điểm | G2: Cự ly (km) | H2: Vận chuyển thô sơ | K2: Vận chuyển khác
C4: Chủng loại | D4: Khối lượng (tấn) | E4: Nơi nhận | F4: Nơi giao | H4: TBKT | I4: Thời gian | K4: TBKT | L4: Thời gian
H5: vật chất (tấn) | I5: Bắt đầu | J5: Kết thúc | K5: vật chất (tấn) | L5: Bắt đầu | M5: Kết thúc
A7: TỔNG SỐ | B7: =DuKienTiLeTBBB!J5 -> 3
A8: GĐCB CĐ | B8: 0 | C8: QN | D8: =KhoiLuongVanTai!F9 -> 0 | E8: HCKT/d | F8: Các hướng | H8: =D8 -> 0 | I8: 17.00 N-3 | J8: 20.00 N-3
C9: QY | D9: =KhoiLuongVanTai!G9 -> 0 | H9: =D9 -> 0 | I9: 17.00 N-2 | J9: 20.00 N-2
C10: DT | D10: =KhoiLuongVanTai!H9 -> 0 | H10: =D10 -> 0 | I10: 17.00 N-2 | J10: 20.00 N-2
C11: VTKT | D11: =KhoiLuongVanTai!D9 -> 0 | H11: =D11 -> 0 | I11: 17.00 N-2 | J11: 20.00 N-2
C12: Đạn | D12: =KhoiLuongVanTai!C9 -> 0 | H12: =D12 -> 0 | I12: 21.00 N-1 | J12: 23.00 N-1
A13: GĐTH CĐ | B13: =B7 -> 3 | C13: QN | D13: =KhoiLuongVanTai!F13 -> 0 | E13: HCKT/d | F13: Các hướng | H13: =D13 -> 0 | I13: Khi có lệnh
C14: QY | D14: =KhoiLuongVanTai!G13 -> 0 | H14: =D14 -> 0 | I14: Khi có lệnh
C15: DT | D15: =KhoiLuongVanTai!H13 -> 0 | H15: =D15 -> 0 | I15: Khi có lệnh
C16: VTKT | D16: =KhoiLuongVanTai!D13 -> 0 | H16: =D16 -> 0 | I16: Khi có lệnh
C17: Đạn | D17: =KhoiLuongVanTai!C13 -> 0 | H17: =D17 -> 0 | I17: Khi có lệnh
A18: Hướng CY | B18: =DuKienTiLeTBBB!J6 -> 32
A19: GĐCB CĐ | C19: QN | E19: HCKT/d | F19: HCY | G19: 0.7 | H19: =D19 -> 0 | I19: 17.00 N-3 | J19: 20.00 N-3
C20: QY | H20: =D20 -> 0 | I20: 17.00 N-2 | J20: 20.00 N-2
C21: DT | H21: =D21 -> 0 | I21: 17.00 N-2 | J21: 20.00 N-2
C22: VTKT | H22: =D22 -> 0 | I22: 17.00 N-2 | J22: 20.00 N-2
C23: Đạn | H23: =D23 -> 0 | I23: 21.00 N-1 | J23: 23.00 N-1
A24: GĐTH CĐ | B24: =B18 -> 32 | C24: QN | E24: HCKT/d | F24: HCY | G24: 1 | H24: =D24 -> 0 | I24: Khi có lệnh
C25: QY | H25: =D25 -> 0 | I25: Khi có lệnh
C26: DT | H26: =D26 -> 0 | I26: Khi có lệnh
C27: VTKT | H27: =D27 -> 0 | I27: Khi có lệnh
C28: Đạn | H28: =D28 -> 0 | I28: Khi có lệnh
A29: Hướng TY | B29: =DuKienTiLeTBBB!J7 -> 19
A30: GĐCB CĐ | C30: QN | E30: HCKT/d | F30: HTY | G30: 1 | H30: =D30 -> 0 | I30: 17.00 N-3 | J30: 20.00 N-3
C31: QY | H31: =D31 -> 0 | I31: 17.00 N-2 | J31: 20.00 N-2
C32: DT | H32: =D32 -> 0 | I32: 17.00 N-2 | J32: 20.00 N-2
C33: VTKT | H33: =D33 -> 0 | I33: 17.00 N-2 | J33: 20.00 N-2
C34: Đạn | H34: =D34 -> 0 | I34: 21.00 N-1 | J34: 23.00 N-1
A35: GĐTH CĐ | B35: =B29 -> 19 | C35: QN | E35: HCKT/d | F35: HTY | G35: 1.5 | H35: =D35 -> 0 | I35: Khi có lệnh
C36: QY | H36: =D36 -> 0 | I36: Khi có lệnh
C37: DT | H37: =D37 -> 0 | I37: Khi có lệnh
C38: VTKT | H38: =D38 -> 0 | I38: Khi có lệnh
C39: Đạn | H39: =D39 -> 0 | I39: Khi có lệnh
A40: LL phía sau | B40: =DuKienTiLeTBBB!J8 -> 10
A41: GĐCB CĐ | C41: QN | E41: HCKT/d | F41: LLDB | G41: 0.7 | H41: =D41 -> 0 | I41: 17.00 N-3 | J41: 20.00 N-3
C42: QY | H42: =D42 -> 0 | I42: 17.00 N-2 | J42: 20.00 N-2
C43: DT | H43: =D43 -> 0 | I43: 17.00 N-2 | J43: 20.00 N-2
...
