Workbook

Sheet KhoiLuongVanTai
A1: 2. Khối lượng vận tải và phân cấp vận chuyển
A2: Nội dung | B2: Khối lượng vận chuyển | M2: Ghi chú
B3: Trang bị kỹ thuật | F3: Vật chất hậu cần | J3: Vật chất khác | K3: Cộng | L3: Người
B4: VKTB | C4: Đạn | D4: VTKT | E4: + | F4: QN | G4: QY | H4: DT | I4: +
A5: Đơn vị tính | B5: tấn | C5: tấn | D5: tấn | E5: tấn | F5: tấn | G5: tấn | H5: tấn | I5: tấn | J5: tấn | K5: tấn | L5: người
A6: Toàn trận | B6: =B7+B11 -> 0 | C6: =C7+C11 -> 0 | D6: =D7+D11 -> 0 | E6: =E7+E11 -> 0 | F6: =F7+F11 -> 0 | G6: =G7+G11 -> 0 | H6: =H7+H11 -> 0 | I6: =I7+I11 -> 0 | J6: =J7+J11 -> 0 | K6: =E6+I6 -> 0
A7: GĐCB | B7: =B8+B9+B10 -> 0 | C7: =C8+C9+C10 -> 0 | D7: =D8+D9+D10 -> 0 | E7: =E8+E9+E10 -> 0 | F7: =F8+F9+F10 -> 0 | G7: =G8+G9+G10 -> 0 | H7: =H8+H9+H10 -> 0 | I7: =I8+I9+I10 -> 0 | ... K7: =K8+K9+K10 -> 0
A8: Trên chuyển
A9: Cấp mình
A10: Dưới chuyển
A11: GĐCĐ | B11: =B12+B13+B14 -> 0 | C11: =C12+C13+C14 -> 0 | D11: =D12+D13+D14 -> 0 | E11: =E12+E13+E14 -> 0 | F11: =F12+F13+F14 -> 0 | G11: =G12+G13+G14 -> 0 | H11: =H12+H13+H14 -> 0 | I11: =I12+I13+I14 -> 0 | ... K11: =K12+K13+K14 -> 0 | L11: =L6 -> 0
A12: Trên chuyển
A13: Cấp mình
A14: Dưới chuyển

Sheet KeHoachVanChuyen
A2: Nội dung, Đơn vị được vận chuyển | B2: Người | C2: TBKT, vật chất HC, KT | E2: Địa điểm | G2: Cự ly (km) | H2: Vận chuyển thô sơ | K2: Vận chuyển khác
C4: Chủng loại | D4: Khối lượng (tấn) | E4: Nơi nhận | F4: Nơi giao | H4: TBKT | I4: Thời gian | K4: TBKT | L4: Thời gian
H5: vật chất (tấn) | I5: Bắt đầu | J5: Kết thúc | K5: vật chất (tấn) | L5: Bắt đầu | M5: Kết thúc
A7: TỔNG SỐ | B7: =DuKienTiLeTBBB!K5 -> 0
A8: GĐCB CĐ | B8: 0 | C8: QN | D8: =KhoiLuongVanTai!F9 -> 0 | E8: HCKT/d | F8: Các hướng | H8: =D8 -> 0 | I8: 17.00 N-3 | J8: 20.00 N-3
C9: QY | D9: =KhoiLuongVanTai!G9 -> 0 | H9: =D9 -> 0 | I9: 17.00 N-2 | J9: 20.00 N-2
C10: DT | D10: =KhoiLuongVanTai!H9 -> 0 | H10: =D10 -> 0 | I10: 17.00 N-2 | J10: 20.00 N-2
C11: VTKT | D11: =KhoiLuongVanTai!D9 -> 0 | H11: =D11 -> 0 | I11: 17.00 N-2 | J11: 20.00 N-2
C12: Đạn | D12: =KhoiLuongVanTai!C9 -> 0 | H12: =D12 -> 0 | I12: 21.00 N-1 | J12: 23.00 N-1
A13: GĐTH CĐ | B13: =B7 -> 0 | C13: QN | D13: =KhoiLuongVanTai!F13 -> 0 | E13: HCKT/d | F13: Các hướng | H13: =D13 -> 0 | I13: Khi có lệnh
C14: QY | D14: =KhoiLuongVanTai!G13 -> 0 | H14: =D14 -> 0 | I14: Khi có lệnh
C15: DT | D15: =KhoiLuongVanTai!H13 -> 0 | H15: =D15 -> 0 | I15: Khi có lệnh
C16: VTKT | D16: =KhoiLuongVanTai!D13 -> 0 | H16: =D16 -> 0 | I16: Khi có lệnh
C17: Đạn | D17: =KhoiLuongVanTai!C13 -> 0 | H17: =D17 -> 0 | I17: Khi có lệnh
A18: Hướng CY | B18: =DuKienTiLeTBBB!K6 -> 0
A19: GĐCB CĐ | C19: QN | E19: HCKT/d | F19: HCY | G19: 0.7 | H19: =D19 -> 0 | I19: 17.00 N-3 | J19: 20.00 N-3
C20: QY | H20: =D20 -> 0 | I20: 17.00 N-2 | J20: 20.00 N-2
C21: DT | H21: =D21 -> 0 | I21: 17.00 N-2 | J21: 20.00 N-2
C22: VTKT | H22: =D22 -> 0 | I22: 17.00 N-2 | J22: 20.00 N-2
C23: Đạn | H23: =D23 -> 0 | I23: 21.00 N-1 | J23: 23.00 N-1
A24: GĐTH CĐ | B24: =B18 -> 0 | C24: QN | E24: HCKT/d | F24: HCY | G24: 1 | H24: =D24 -> 0 | I24: Khi có lệnh
C25: QY | H25: =D25 -> 0 | I25: Khi có lệnh
C26: DT | H26: =D26 -> 0 | I26: Khi có lệnh
C27: VTKT | H27: =D27 -> 0 | I27: Khi có lệnh
C28: Đạn | H28: =D28 -> 0 | I28: Khi có lệnh
A29: Hướng TY | B29: =DuKienTiLeTBBB!K7 -> 0
A30: GĐCB CĐ | C30: QN | E30: HCKT/d | F30: HTY | G30: 1 | H30: =D30 -> 0 | I30: 17.00 N-3 | J30: 20.00 N-3
C31: QY | H31: =D31 -> 0 | I31: 17.00 N-2 | J31: 20.00 N-2
C32: DT | H32: =D32 -> 0 | I32: 17.00 N-2 | J32: 20.00 N-2
C33: VTKT | H33: =D33 -> 0 | I33: 17.00 N-2 | J33: 20.00 N-2
C34: Đạn | H34: =D34 -> 0 | I34: 21.00 N-1 | J34: 23.00 N-1
A35: GĐTH CĐ | B35: =B29 -> 0 | C35: QN | E35: HCKT/d | F35: HTY | G35: 1.5 | H35: =D35 -> 0 | I35: Khi có lệnh
C36: QY | H36: =D36 -> 0 | I36: Khi có lệnh
C37: DT | H37: =D37 -> 0 | I37: Khi có lệnh
C38: VTKT | H38: =D38 -> 0 | I38: Khi có lệnh
C39: Đạn | H39: =D39 -> 0 | I39: Khi có lệnh
A40: LL phía sau | B40: =DuKienTiLeTBBB!K8 -> 0
A41: GĐCB CĐ | C41: QN | E41: HCKT/d | F41: LLDB | G41: 0.7 | H41: =D41 -> 0 | I41: 17.00 N-3 | J41: 20.00 N-3
C42: QY | H42: =D42 -> 0 | I42: 17.00 N-2 | J42: 20.00 N-2
C43: DT | H43: =D43 -> 0 | I43: 17.00 N-2 | J43: 20.00 N-2
...

Sheet DuKienTiLeTBBB
