Workbook

Sheet QSTBKT
A3: LỰC LƯỢNG
A6: 1. Trong biên chế
A7: dBB
A8: 2. LL phối thuộc
A9: 1 cO100/e
A10: 1 cSPG-9/e
A11: 1 cSMPK 12,7mm/e
A12: 1b VTB/e
A13: 1 tổ QY/e
A14: 1 bHH/f
A15: 1 c CB(-)/e
A16: 1 tổ SC/e
... A81: Tổng

Sheet ChiLenhHCKT

Sheet PhanCapVCHC

Sheet TinhHinhVC

Sheet VCHCVTKT
A1: Quy định, phân cấp dự trữ vật chất hậu cần, vật tư kỹ thuật | AE1: Tỷ lệ TBBB
A3: Chỉ tiêu | B3: ĐVT | C3: TL ĐVT | D3: TL ĐVT (d) | E3: TL ĐVT (PT) | F3: Quy định dự trữ, tiêu thụ | L3: Hiện có | Q3: PC TQĐ | S3: Bổ sung | Z3: Kế hoạch tiếp nhận, bảo đảm
F4: Quy định dự trữ | G4: Tiêu thụ | I4: PC SCĐ | L4: Kho/d | N4: ĐV | P4: + | S4: GĐCB | W4: GĐCĐ | Y4: + | Z4: Thời gian | AA4: Địa điểm | AB4: Phương thức | AC4: Trách nhiệm vận chuyển
G5: GĐCB | H5: GĐCĐ | L5: d | M5: PT | N5: d | O5: PT | S5: Kho/d | U5: ĐV | W5: Kho/d | X5: ĐV
I6: Kho/d | J6: ĐV | K6: + | Q6: Kho/d | R6: ĐV | S6: d | T6: PT | U6: d | V6: PT
A7: I. Toàn d | F7: =F8+F14+F19+F21 -> 0 | G7: =G8+G14+G19+G21 -> 0 | H7: =H8+H14+H19+H21 -> 0 | I7: =I8+I14+I19+I21 -> 0 | J7: =J8+J14+J19+J21 -> 0 | K7: =K8+K14+K19+K21 -> 0 | L7: =L8+L14+L19+L21 -> 0 | M7: =M8+M14+M19+M21 -> 0 | ... O7: =O8+O14+O19+O21 -> 0 | P7: =L7+M7+N7+O7 -> 0 | Q7: =Q8+Q14+Q19+Q21 -> 0 | R7: =R8+R14+R19+R21 -> 0 | S7: =S8+S14+S19+S21 -> 0 | T7: =T8+T14+T19 -> 0 | U7: =U8+U14+U19+U21 -> 0 | V7: =V8+V14+V19 -> 0 | W7: =ABS(W8)+ABS(W14)+ABS(W19)+ABS(W21) -> 0 | X7: =X8+X14+X19+X21 -> 0 | Y7: =Y8+Y14+Y19+Y21 -> 0
A8: 1. Quân nhu | B8: Tấn | F8: =G8+H8+J8 -> 0 | G8: =SUMPRODUCT($C$9:$C$13,G9:G13)/1000 -> 0 | H8: =SUMPRODUCT($C$9:$C$13,H9:H13)/1000 -> 0 | I8: =SUMPRODUCT($C$9:$C$13,I9:I13)/1000 -> 0 | J8: =SUMPRODUCT($C$9:$C$13,J9:J13)/1000 -> 0 | K8: =I8+J8 -> 0 | L8: =SUMPRODUCT($D$9:$D$13,L9:L13)/1000 -> 0 | M8: =SUMPRODUCT($E$9:$E$13,M9:M13)/1000 -> 0 | N8: =SUMPRODUCT($D$9:$D$13,N9:N13)/1000 -> 0 | O8: =SUMPRODUCT($E$9:$E$13,O9:O13)/1000 -> 0 | P8: =L8+M8+N8+O8 -> 0 | Q8: =SUMPRODUCT($C$9:$C$13,Q9:Q13)/1000 -> 0 | R8: =SUMPRODUCT($C$9:$C$13,R9:R13)/1000 -> 0 | S8: =SUMPRODUCT($D$9:$D$13,S9:S13)/1000 -> 0 | T8: =SUMPRODUCT($E$9:$E$13,T9:T13)/1000 -> 0 | U8: =SUMPRODUCT($D$9:$D$13,U9:U13)/1000 -> 0 | V8: =SUMPRODUCT($E$9:$E$13,V9:V13)/1000 -> 0 | W8: =SUMPRODUCT($C$9:$C$13,W9:W13)/1000 -> 0 | X8: =SUMPRODUCT($C$9:$C$13,X9:X13)/1000 -> 0 | Y8: =F8-P8 -> 0
A9: LTTP | B9: N/a | C9: =D9+E9 -> 0 | D9: =1.2*QSTBKT!B6 -> 0 | E9: =1.2*QSTBKT!B8 -> 0 | F9: =ChiLenhHCKT!D17 -> 0 | G9: =ChiLenhHCKT!G17 -> 0 | H9: =ChiLenhHCKT!H17 -> 0 | I9: =PhanCapVCHC!G6 -> 0 | J9: =PhanCapVCHC!H6 -> 0 | K9: =ChiLenhHCKT!F17 -> 0 | L9: =TinhHinhVC!D16 -> 0 | M9: 0 | N9: =TinhHinhVC!E16 -> 0 | O9: 3 | Q9: =PhanCapVCHC!D6 -> 0 | R9: =PhanCapVCHC!E6 -> 0 | S9: =Q9-L9 -> 0 | T9: =Q9-M9 -> 0 | U9: =G9+R9-N9 -> 0 | V9: =G9+R9-O9 -> -3 | W9: =I9-Q9 -> 0 | X9: =H9+J9-R9 -> 0
A10: Lương khô | B10: N/a | C10: =D10+E10 -> 0 | D10: =0.75*QSTBKT!B6 -> 0 | E10: =0.75*QSTBKT!B8 -> 0 | F10: =ChiLenhHCKT!D18 -> 0 | G10: =ChiLenhHCKT!G18 -> 0 | H10: =ChiLenhHCKT!H18 -> 0 | I10: =PhanCapVCHC!G7 -> 0 | J10: =PhanCapVCHC!H7 -> 0 | K10: =ChiLenhHCKT!F18 -> 0 | L10: =TinhHinhVC!D17 -> 0 | M10: 0 | N10: =TinhHinhVC!E17 -> 0 | O10: 1 | Q10: =PhanCapVCHC!D7 -> 0 | R10: =PhanCapVCHC!E7 -> 0 | S10: =Q10-L10 -> 0 | T10: =Q10-M10 -> 0 | U10: =G10+R10-N10 -> 0 | V10: =G10+R10-O10 -> -1 | W10: =I10-Q10 -> 0 | X10: =H10+J10-R10 -> 0
A11: ĐSTB | B11: %QS | C11: =D11+E11 -> 0 | D11: =0.01*QSTBKT!B6*1.8/7 -> 0 | E11: =0.01*QSTBKT!B8*1.8/7 -> 0 | F11: =ChiLenhHCKT!D19 -> 0 | G11: =ChiLenhHCKT!G19 -> 0 | H11: =ChiLenhHCKT!H19 -> 0 | I11: =PhanCapVCHC!G8 -> 0 | J11: =PhanCapVCHC!H8 -> 0 | K11: =ChiLenhHCKT!F19 -> 0 | L11: =TinhHinhVC!D18 -> 0 | M11: 0 | N11: =TinhHinhVC!E18 -> 0 | O11: 0 | Q11: =PhanCapVCHC!D8 -> 0 | R11: =PhanCapVCHC!E8 -> 0 | S11: =Q11-L11 -> 0 | T11: - | U11: =G11+R11-N11 -> 0 | V11: - | W11: =I11-Q11 -> 0 | X11: =H11+J11-R11 -> 0
A12: QLCĐ | B12: %QS | C12: =D12+E12 -> 0 | D12: =0.01*QSTBKT!B6*2 -> 0 | E12: =0.01*QSTBKT!B8*2 -> 0 | F12: =ChiLenhHCKT!D20 -> 0 | G12: =ChiLenhHCKT!G20 -> 0 | H12: =ChiLenhHCKT!H20 -> 0 | I12: =PhanCapVCHC!G9 -> 0 | J12: =PhanCapVCHC!H9 -> 0 | K12: =ChiLenhHCKT!F20 -> 0 | L12: =TinhHinhVC!D19 -> 0 | M12: 0 | N12: =TinhHinhVC!E19 -> 0 | O12: 100 | Q12: =PhanCapVCHC!D9 -> 0 | R12: =PhanCapVCHC!E9 -> 0 | S12: =Q12-L12 -> 0 | T12: =Q12-M12 -> 0 | U12: =G12+R12-N12 -> 0 | V12: =G12+R12-O12 -> -100 | W12: =I12-Q12 -> 0 | X12: =H12+J12-R12 -> 0
A13: QTCĐ | B13: %QS | C13: =D13+E13 -> 0 | D13: =0.01*QSTBKT!B6*3 -> 0 | E13: =0.01*QSTBKT!B8*3 -> 0 | F13: =ChiLenhHCKT!D21 -> 0 | G13: =ChiLenhHCKT!G21 -> 0 | H13: =ChiLenhHCKT!H21 -> 0 | I13: =PhanCapVCHC!G10 -> 0 | J13: =PhanCapVCHC!H10 -> 0 | K13: =ChiLenhHCKT!F21 -> 0 | L13: =TinhHinhVC!D20 -> 0 | M13: 0 | N13: =TinhHinhVC!E20 -> 0 | O13: 100 | Q13: =PhanCapVCHC!D10 -> 0 | R13: =PhanCapVCHC!E10 -> 0 | S13: =Q13-L13 -> 0 | T13: =Q13-M13 -> 0 | U13: =G13+R13-N13 -> 0 | V13: =G13+R13-O13 -> -100 | W13: =I13-Q13 -> 0 | X13: =H13+J13-R13 -> 0
A14: 2. Quân y | B14: Tấn | F14: =G14+H14+J14 -> 0 | G14: =SUMPRODUCT($C$15:$C$18,G15:G18)/1000 -> 0 | H14: =SUMPRODUCT($C$15:$C$18,H15:H18)/1000 -> 0 | I14: =SUMPRODUCT($C$15:$C$18,I15:I18)/1000 -> 0 | J14: =SUMPRODUCT($C$15:$C$18,J15:J18)/1000 -> 0 | K14: =SUMPRODUCT($C$15:$C$18,K15:K18)/1000 -> 0 | L14: =(SUMPRODUCT($C$15:$C$17,L15:L17)+L18*$D$18)/1000 -> 0 | M14: =(SUMPRODUCT($C$15:$C$17,M15:M17)+M18*$E$18)/1000 -> 0 | N14: =(SUMPRODUCT($C$15:$C$17,N15:N17)+N18*$D$18)/1000 -> 0 | O14: =(SUMPRODUCT($C$15:$C$17,O15:O17)+O18*$E$18)/1000 -> 0 | P14: =L14+M14+N14+O14 -> 0 | Q14: =SUMPRODUCT($C$15:$C$18,Q15:Q18)/1000 -> 0 | R14: =SUMPRODUCT($C$15:$C$18,R15:R18)/1000 -> 0 | S14: =(SUMPRODUCT($C$15:$C$17,S15:S17)+S18*$D$18)/1000 -> 0 | T14: =(SUMPRODUCT($C$15:$C$17,T15:T17)+T18*$E$18)/1000 -> 0 | U14: =(SUMPRODUCT($C$15:$C$17,U15:U17)+U18*$D$18)/1000 -> 0 | V14: =(SUMPRODUCT($C$15:$C$17,V15:V17)+V18*$E$18)/1000 -> 0 | W14: =SUMPRODUCT($C$15:$C$18,W15:W18)/1000 -> 0 | X14: =SUMPRODUCT($C$15:$C$18,X15:X18)/1000 -> 0 | Y14: =F14-P14 -> 0
A15: Túi y sĩ | B15: Túi | C15: 6 | D15: 6 | E15: 6 | F15: =ChiLenhHCKT!D23 -> 0 | G15: =ChiLenhHCKT!G23 -> 0 | H15: =ChiLenhHCKT!H23 -> 0 | I15: =PhanCapVCHC!G12 -> 0 | J15: =PhanCapVCHC!H12 -> 0 | K15: =ChiLenhHCKT!F23 -> 0 | L15: =TinhHinhVC!D22 -> 0 | M15: 0 | N15: =TinhHinhVC!E22 -> 0 | O15: 0 | Q15: =PhanCapVCHC!D12 -> 0 | R15: =PhanCapVCHC!E12 -> 0 | S15: =Q15-L15 -> 0 | T15: - | U15: =G15+R15-N15 -> 0 | V15: - | W15: =I15-Q15 -> 0 | X15: =H15+J15-R15 -> 0
A16: Túi y tá | B16: Túi | C16: 4 | D16: 4 | E16: 4 | F16: =ChiLenhHCKT!D24 -> 0 | G16: =ChiLenhHCKT!G24 -> 0 | H16: =ChiLenhHCKT!H24 -> 0 | I16: =PhanCapVCHC!G13 -> 0 | J16: =PhanCapVCHC!H13 -> 0 | K16: =ChiLenhHCKT!F24 -> 0 | L16: =TinhHinhVC!D23 -> 0 | M16: 0 | N16: =TinhHinhVC!E23 -> 0 | O16: 0 | Q16: =PhanCapVCHC!D13 -> 0 | R16: =PhanCapVCHC!E13 -> 0 | S16: =Q16-L16 -> 0 | T16: - | U16: =G16+R16-N16 -> 0 | V16: - | W16: =I16-Q16 -> 0 | X16: =H16+J16-R16 -> 0
A17: Túi cứu thương | B17: Túi | C17: 2 | D17: 2 | E17: 2 | F17: =ChiLenhHCKT!D25 -> 0 | G17: =ChiLenhHCKT!G25 -> 0 | H17: =ChiLenhHCKT!H25 -> 0 | I17: =PhanCapVCHC!G14 -> 0 | J17: =PhanCapVCHC!H14 -> 0 | K17: =ChiLenhHCKT!F25 -> 0 | L17: =TinhHinhVC!D24 -> 0 | M17: 0 | N17: =TinhHinhVC!E24 -> 0 | O17: 0 | Q17: =PhanCapVCHC!D14 -> 0 | R17: =PhanCapVCHC!E14 -> 0 | S17: =Q17-L17 -> 0 | T17: - | U17: =G17+R17-N17 -> 0 | V17: - | W17: =I17-Q17 -> 0 | X17: =H17+J17-R17 -> 0
A18: BCN | B18: C/ng | C18: =D18+E18 -> 0 | D18: =0.07*QSTBKT!B6 -> 0 | E18: =0.07*QSTBKT!B8 -> 0 | F18: =ChiLenhHCKT!D26 -> 0 | G18: =ChiLenhHCKT!G26 -> 0 | H18: =ChiLenhHCKT!H26 -> 0 | I18: =PhanCapVCHC!G15 -> 0 | J18: =PhanCapVCHC!H15 -> 0 | K18: =ChiLenhHCKT!F26 -> 0 | L18: =TinhHinhVC!D25 -> 0 | M18: 0 | N18: =TinhHinhVC!E25 -> 0 | O18: 1 | Q18: =PhanCapVCHC!D15 -> 0 | R18: =PhanCapVCHC!E15 -> 0 | S18: =Q18-L18 -> 0 | T18: =Q18-M18 -> 0 | U18: =G18+R18-N18 -> 0 | V18: =G18+R18-O18 -> -1 | W18: =I18-Q18 -> 0 | X18: =H18+J18-R18 -> 0
A19: 3. Doanh trại | B19: Tấn | F19: =$C$20*F20/1000 -> 0 | G19: =$C$20*G20/1000 -> 0 | H19: =$C$20*H20/1000 -> 0 | I19: =$C$20*I20/1000 -> 0 | J19: =$C$20*J20/1000 -> 0 | K19: =$C$20*K20/1000 -> 0 | L19: =L20*$D$20/1000 -> 0 | M19: =M20*$E$20 -> 0 | N19: =N20*$D$20/1000 -> 0 | O19: =O20*$E$20/1000 -> 0 | P19: =L19+M19+N19+O19 -> 0 | Q19: =$C$20*Q20/1000 -> 0 | R19: =$C$20*R20/1000 -> 0 | S19: =S20*$D$20/1000 -> 0 | T19: =T20*$E$20/1000 -> 0 | U19: =U20*$D$20/1000 -> 0 | V19: =V20*$E$20/1000 -> 0 | W19: =$C$20*W20/1000 -> 0 | X19: =$C$20*X20/1000 -> 0 | Y19: =F19-P19 -> 0
A20: Dầu thắp | B20: ngày | C20: =D20+E20 -> 0 | D20: =QSTBKT!B6*0.5/30 -> 0 | E20: =QSTBKT!B8*0.5/30 -> 0 | F20: =ChiLenhHCKT!D28 -> 0 | G20: =ChiLenhHCKT!G28 -> 0 | H20: =ChiLenhHCKT!H28 -> 0 | I20: =PhanCapVCHC!G17 -> 0 | J20: =PhanCapVCHC!H17 -> 0 | K20: =ChiLenhHCKT!F28 -> 0 | L20: =TinhHinhVC!D27 -> 0 | M20: 0 | N20: =TinhHinhVC!E27 -> 0 | O20: 3 | Q20: =PhanCapVCHC!D17 -> 0 | R20: =PhanCapVCHC!E17 -> 0 | S20: =Q20-L20 -> 0 | T20: =Q20-M20 -> 0 | U20: =G20+R20-N20 -> 0 | V20: =G20+R20-O20 -> -3 | W20: =I20-Q20 -> 0 | X20: =H20+J20-R20 -> 0
A21: 4. VTKT | B21: Tấn | F21: =ChiLenhHCKT!D29 -> 0 | G21: =ChiLenhHCKT!G29 -> 0 | H21: =ChiLenhHCKT!H29 -> 0 | I21: =PhanCapVCHC!G18 -> 0 | J21: =PhanCapVCHC!H18 -> 0 | K21: =ChiLenhHCKT!F29 -> 0 | L21: =TinhHinhVC!D29 -> 0 | M21: 0 | N21: =TinhHinhVC!E29 -> 0 | O21: 0 | P21: =L21+M21+N21+O21 -> 0 | Q21: =PhanCapVCHC!D18 -> 0 | R21: =PhanCapVCHC!E18 -> 0 | S21: =Q21-L21 -> 0 | T21: - | U21: =G21+R21-N21 -> 0 | V21: - | W21: =I21-Q21 -> 0 | X21: =H21+J21-R21 -> 0 | Y21: =F21-P21 -> 0
A22: II. Hướng chủ yếu | F22: =F23+F29+F34+F36 -> 0 | G22: =G23+G29+G34+G36 -> 0 | H22: =H23+H29+H34+H36 -> 0 | I22: - | J22: =J23+J29+J34+J36 -> 0 | K22: =K23+K29+K34+K36 -> 0 | L22: - | M22: - | N22: =N23+N29+N34+N36 -> 0 | O22: - | P22: =P23+P29+P34+P36 -> 0 | Q22: - | R22: =R23+R29+R34+R36 -> 0 | S22: - | T22: - | U22: =U23+U29+U34+U36 -> 0 | V22: - | W22: - | X22: =X23+X29+X34+X36 -> 0 | Y22: =Y23+Y29+Y34+Y36 -> 0
A23: 1. Quân nhu | B23: Tấn | F23: =SUMPRODUCT($C$24:$C$28,F24:F28)/1000 -> 0 | G23: =SUMPRODUCT($C$24:$C$28,G24:G28)/1000 -> 0 | H23: =SUMPRODUCT($C$24:$C$28,H24:H28)/1000 -> 0 | I23: - | J23: =SUMPRODUCT($C$24:$C$28,J24:J28)/1000 -> 0 | K23: =SUMPRODUCT($C$24:$C$28,K24:K28)/1000 -> 0 | L23: - | M23: - | N23: =SUMPRODUCT($C$24:$C$28,N24:N28)/1000 -> 0 | O23: - | P23: =N23 -> 0 | Q23: - | R23: =SUMPRODUCT($C$24:$C$28,R24:R28)/1000 -> 0 | S23: - | T23: - | U23: =G23+R23-N23 -> 0 | V23: - | W23: - | X23: =H23+J23-R23 -> 0 | Y23: =F23-N23 -> 0
A24: LTTP | B24: N/a | C24: =1.2*QSTBKT!B36 -> 0 | F24: =F9 -> 0 | G24: =G9 -> 0 | H24: =H9 -> 0 | I24: - | J24: =J9 -> 0 | K24: =J24 -> 0 | L24: - | M24: - | N24: =N9 -> 0 | O24: - | Q24: - | R24: =R9 -> 0 | S24: - | T24: - | U24: =G24+R24-N24 -> 0 | V24: - | W24: - | X24: =H24+J24-R24 -> 0
A25: Lương khô | B25: N/a | C25: =0.75*QSTBKT!B36 -> 0 | F25: =F10 -> 0 | G25: =G10 -> 0 | H25: =H10 -> 0 | I25: - | J25: =J10 -> 0 | K25: =J25 -> 0 | L25: - | M25: - | N25: =N10 -> 0 | O25: - | Q25: - | R25: =R10 -> 0 | S25: - | T25: - | U25: =G25+R25-N25 -> 0 | V25: - | W25: - | X25: =H25+J25-R25 -> 0
A26: ĐSTB | B26: %QS | C26: - | F26: - | G26: - | H26: - | I26: - | J26: - | K26: - | L26: - | M26: - | N26: - | O26: - | P26: - | Q26: - | R26: - | S26: - | T26: - | U26: - | V26: - | W26: - | X26: - | Y26: -
A27: QLCĐ | B27: %QS | C27: =0.01*QSTBKT!B36*2 -> 0 | F27: =F12 -> 0 | G27: =G12 -> 0 | H27: =H12 -> 0 | I27: - | J27: =J12 -> 0 | K27: =J27 -> 0 | L27: - | M27: - | N27: =N12 -> 0 | O27: - | Q27: - | R27: =R12 -> 0 | S27: - | T27: - | U27: =G27+R27-N27 -> 0 | V27: - | W27: - | X27: =H27+J27-R27 -> 0
A28: QTCĐ | B28: %QS | C28: =0.01*QSTBKT!B36*3 -> 0 | F28: =F13 -> 0 | G28: =G13 -> 0 | H28: =H13 -> 0 | I28: - | J28: =J13 -> 0 | K28: =J28 -> 0 | L28: - | M28: - | N28: =N13 -> 0 | O28: - | Q28: - | R28: =R13 -> 0 | S28: - | T28: - | U28: =G28+R28-N28 -> 0 | V28: - | W28: - | X28: =H28+J28-R28 -> 0
A29: 2. Quân y | B29: Tấn | F29: =SUMPRODUCT($C$30:$C$33,F30:F33)/1000 -> 0 | G29: =SUMPRODUCT($C$30:$C$33,G30:G33)/1000 -> 0 | H29: =SUMPRODUCT($C$30:$C$33,H30:H33)/1000 -> 0 | I29: - | J29: =SUMPRODUCT($C$30:$C$33,J30:J33)/1000 -> 0 | K29: =J29 -> 0 | L29: - | M29: - | N29: =SUMPRODUCT($C$30:$C$33,N30:N33)/1000 -> 0 | O29: - | P29: =N29 -> 0 | Q29: - | R29: =SUMPRODUCT($C$30:$C$33,R30:R33)/1000 -> 0 | S29: - | T29: - | U29: =G29+R29-N29 -> 0 | V29: - | W29: - | X29: =H29+J29-R29 -> 0 | Y29: =F29-N29 -> 0
A30: Túi y sĩ | B30: Túi | C30: 6 | I30: - | K30: =J30 -> 0 | L30: - | M30: - | O30: - | Q30: - | S30: - | T30: - | U30: =G30+R30-N30 -> 0 | V30: - | W30: - | X30: =H30+J30-R30 -> 0
A31: Túi y tá | B31: Túi | C31: 4 | I31: - | K31: =J31 -> 0 | L31: - | M31: - | O31: - | Q31: - | S31: - | T31: - | U31: =G31+R31-N31 -> 0 | V31: - | W31: - | X31: =H31+J31-R31 -> 0
A32: Túi cứu thương | B32: Túi | C32: 2 | I32: - | K32: =J32 -> 0 | L32: - | M32: - | O32: - | Q32: - | S32: - | T32: - | U32: =G32+R32-N32 -> 0 | V32: - | W32: - | X32: =H32+J32-R32 -> 0
A33: BCN | B33: C/ng | C33: =0.07*QSTBKT!B36 -> 0 | F33: =F18 -> 0 | G33: =G18 -> 0 | H33: =H18 -> 0 | I33: - | J33: =J18 -> 0 | K33: =J33 -> 0 | L33: - | M33: - | N33: =N18 -> 0 | O33: - | Q33: - | R33: =R18 -> 0 | S33: - | T33: - | U33: =G33+R33-N33 -> 0 | V33: - | W33: - | X33: =H33+J33-R33 -> 0
A34: 3. Doanh trại | B34: Tấn | F34: =F35*$C$35/1000 -> 0 | G34: =G35*$C$35/1000 -> 0 | H34: =H35*$C$35/1000 -> 0 | I34: - | J34: =J35*$C$35/1000 -> 0 | K34: =J34 -> 0 | L34: - | M34: - | N34: =N35*$C$35/1000 -> 0 | O34: - | P34: =N34 -> 0 | Q34: - | R34: =R35*$C$35/1000 -> 0 | S34: - | T34: - | U34: =G34+R34-N34 -> 0 | V34: - | W34: - | X34: =H34+J34-R34 -> 0 | Y34: =F34-N34 -> 0
A35: Dầu thắp | B35: ngày | C35: =0.5*QSTBKT!B36/30 -> 0 | F35: =F20 -> 0 | G35: =G20 -> 0 | H35: =H20 -> 0 | I35: - | J35: =J20 -> 0 | K35: =J35 -> 0 | L35: - | M35: - | N35: =N20 -> 0 | O35: - | Q35: - | R35: =R20 -> 0 | S35: - | T35: - | U35: =G35+R35-N35 -> 0 | V35: - | W35: - | X35: =H35+J35-R35 -> 0
A36: 4. VTKT | B36: Tấn | I36: - | K36: =J36 -> 0 | L36: - | M36: - | O36: - | P36: =N36 -> 0 | Q36: - | S36: - | T36: - | U36: =G36+R36-N36 -> 0 | V36: - | W36: - | X36: =H36+J36-R36 -> 0 | Y36: =F36-N36 -> 0
A37: II. Hướng thứ yếu | F37: =F38+F44+F49+F51 -> 0 | G37: =G38+G44+G49+G51 -> 0 | H37: =H38+H44+H49+H51 -> 0 | I37: - | J37: =J38+J44+J49+J51 -> 0 | K37: =K38+K44+K49+K51 -> 0 | L37: - | M37: - | N37: =N38+N44+N49+N51 -> 0 | O37: - | P37: =P38+P44+P49+P51 -> 0 | Q37: - | R37: =R38+R44+R49+R51 -> 0 | S37: - | T37: - | U37: =U38+U44+U49+U51 -> 0 | V37: - | W37: - | X37: =X38+X44+X49+X51 -> 0 | Y37: =Y38+Y44+Y49+Y51 -> 0
A38: 1. Quân nhu | B38: Tấn | F38: =SUMPRODUCT($C$39:$C$43,F39:F43)/1000 -> 0 | G38: =SUMPRODUCT($C$39:$C$43,G39:G43)/1000 -> 0 | H38: =SUMPRODUCT($C$39:$C$43,H39:H43)/1000 -> 0 | I38: - | J38: =SUMPRODUCT($C$39:$C$43,J39:J43)/1000 -> 0 | K38: =J38 -> 0 | L38: - | M38: - | N38: =SUMPRODUCT($C$39:$C$43,N39:N43)/1000 -> 0 | O38: - | P38: =N38 -> 0 | Q38: - | R38: =SUMPRODUCT($C$39:$C$43,R39:R43)/1000 -> 0 | S38: - | T38: - | U38: =SUMPRODUCT($C$39:$C$43,U39:U43)/1000 -> 0 | V38: - | W38: - | X38: =H38+J38-R38 -> 0 | Y38: =F38-N38 -> 0
A39: LTTP | B39: N/a | C39: =1.2*QSTBKT!B51 -> 0 | F39: =F24 -> 0 | G39: =G24 -> 0 | H39: =H24 -> 0 | I39: - | J39: =J24 -> 0 | K39: =J39 -> 0 | L39: - | M39: - | N39: =N24 -> 0 | O39: - | Q39: - | R39: =R24 -> 0 | S39: - | T39: - | U39: =G39+R39-N39 -> 0 | V39: - | W39: - | X39: =H39+J39-R39 -> 0
A40: Lương khô | B40: N/a | C40: =0.75*QSTBKT!B51 -> 0 | F40: =F25 -> 0 | G40: =G25 -> 0 | H40: =H25 -> 0 | I40: - | J40: =J25 -> 0 | K40: =J40 -> 0 | L40: - | M40: - | N40: =N25 -> 0 | O40: - | Q40: - | R40: =R25 -> 0 | S40: - | T40: - | U40: =G40+R40-N40 -> 0 | V40: - | W40: - | X40: =H40+J40-R40 -> 0
A41: ĐSTB | B41: %QS | C41: - | F41: =F26 -> - | G41: =G26 -> - | H41: =H26 -> - | I41: - | J41: =J26 -> - | K41: =J41 -> - | L41: - | M41: - | N41: =N26 -> - | O41: - | Q41: - | R41: =R26 -> - | S41: - | T41: - | U41: - | V41: - | W41: - | X41: -
...
